<?xml version="1.0" ?>
<!-- =================================================================================== -->
<!-- |    This document was autogenerated by xacro from src/tidybot_description/urdf/tidybot.xacro | -->
<!-- |    EDITING THIS FILE BY HAND IS NOT RECOMMENDED                                 | -->
<!-- =================================================================================== -->
<robot name="tidybot">
  <!-- <xacro:load_base prefix=""/> -->
  <link name="world"/>
  <link name="base">
    <inertial>
      <origin rpy="0.0 0.0 0.0" xyz="0.0 0.0 0.035"/>
      <mass value="60.0"/>
      <inertia ixx="0.001" ixy="0" ixz="0" iyy="0.001" iyz="0" izz="0.001"/>
    </inertial>
    <visual name="bumper">
      <origin rpy="-2.442021632452952 -1.5707963267948966 0.0" xyz="-1.3915598211675165e-07 -2.058962502098711e-07 0.05386474576457055"/>
      <geometry>
        <mesh filename="file:///home/janchen/Documents/ros2/tidybot_ws/install/tidybot_description/share/tidybot_description/meshes/base/bumper.stl"/>
      </geometry>
      <material name="white"/>
    </visual>
    <collision name="bumper">
      <origin rpy="-2.442021632452952 -1.5707963267948966 0.0" xyz="-1.3915598211675165e-07 -2.058962502098711e-07 0.05386474576457055"/>
      <geometry>
        <mesh filename="file:///home/janchen/Documents/ros2/tidybot_ws/install/tidybot_description/share/tidybot_description/meshes/base/bumper.stl"/>
      </geometry>
    </collision>
    <visual name="bottom_plate">
      <origin rpy="1.6659662035857206 -1.5707963267948966 0.0" xyz="4.155854111430312e-11 1.8201972332496634e-11 0.08495000004768373"/>
      <geometry>
        <mesh filename="file:///home/janchen/Documents/ros2/tidybot_ws/install/tidybot_description/share/tidybot_description/meshes/base/bottom_plate.stl"/>
      </geometry>
      <material name="white"/>
    </visual>
    <collision name="bottom_plate">
      <origin rpy="1.6659662035857206 -1.5707963267948966 0.0" xyz="4.155854111430312e-11 1.8201972332496634e-11 0.08495000004768373"/>
      <geometry>
        <mesh filename="file:///home/janchen/Documents/ros2/tidybot_ws/install/tidybot_description/share/tidybot_description/meshes/base/bottom_plate.stl"/>
      </geometry>
    </collision>
    <visual name="body">
      <origin rpy="-1.5707963267948966 -1.570779305272103 3.141592653589793" xyz="7.590768644441668e-06 -6.000635064190085e-10 0.20330222068596052"/>
      <geometry>
        <mesh filename="file:///home/janchen/Documents/ros2/tidybot_ws/install/tidybot_description/share/tidybot_description/meshes/base/body.stl"/>
      </geometry>
      <material name="white"/>
    </visual>
    <collision name="body">
      <origin rpy="-1.5707963267948966 -1.570779305272103 3.141592653589793" xyz="7.590768644441668e-06 -6.000635064190085e-10 0.20330222068596052"/>
      <geometry>
        <mesh filename="file:///home/janchen/Documents/ros2/tidybot_ws/install/tidybot_description/share/tidybot_description/meshes/base/body.stl"/>
      </geometry>
    </collision>
    <visual name="top_plate">
      <origin rpy="1.6906681075416252 -1.5707963267948966 0.0" xyz="-2.9658670629084936e-11 -3.476524862019053e-11 0.3216499984264373"/>
      <geometry>
        <mesh filename="file:///home/janchen/Documents/ros2/tidybot_ws/install/tidybot_description/share/tidybot_description/meshes/base/top_plate.stl"/>
      </geometry>
      <material name="white"/>
    </visual>
    <collision name="top_plate">
      <origin rpy="1.6906681075416252 -1.5707963267948966 0.0" xyz="-2.9658670629084936e-11 -3.476524862019053e-11 0.3216499984264373"/>
      <geometry>
        <mesh filename="file:///home/janchen/Documents/ros2/tidybot_ws/install/tidybot_description/share/tidybot_description/meshes/base/top_plate.stl"/>
      </geometry>
    </collision>
    <visual name="arm_plate">
      <origin rpy="1.5707963267948966 -1.5707963267948966 0.0" xyz="-2.7580994002430455e-12 -3.3382504263355704e-12 0.32999999883475684"/>
      <geometry>
        <mesh filename="file:///home/janchen/Documents/ros2/tidybot_ws/install/tidybot_description/share/tidybot_description/meshes/base/arm_plate.stl"/>
      </geometry>
      <material name="white"/>
    </visual>
    <collision name="arm_plate">
      <origin rpy="1.5707963267948966 -1.5707963267948966 0.0" xyz="-2.7580994002430455e-12 -3.3382504263355704e-12 0.32999999883475684"/>
      <geometry>
        <mesh filename="file:///home/janchen/Documents/ros2/tidybot_ws/install/tidybot_description/share/tidybot_description/meshes/base/arm_plate.stl"/>
      </geometry>
    </collision>
  </link>
  <link name="joint_x_jointbody">
    <inertial>
      <origin rpy="0.0 0.0 0.0" xyz="0.0 0.0 0.0"/>
      <mass value="0.001"/>
      <inertia ixx="1e-09" ixy="0" ixz="0" iyy="1e-09" iyz="0" izz="1e-09"/>
    </inertial>
  </link>
  <joint name="joint_x" type="prismatic">
    <origin rpy="0.0 0.0 0.0" xyz="0.0 0.0 0.0"/>
    <parent link="world"/>
    <child link="joint_x_jointbody"/>
    <axis xyz="1 0 0"/>
    <limit effort="100" lower="-10.0" upper="10.0" velocity="1"/>
    <dynamics damping="1.0" friction="1.0"/>
  </joint>
  <transmission name="joint_x_trans">
    <type>transmission_interface/SimpleTransmission</type>
    <joint name="joint_x"/>
    <actuator name="joint_x_motor">
      <mechanicalReduction>1</mechanicalReduction>
    </actuator>
  </transmission>
  <link name="joint_y_jointbody">
    <inertial>
      <origin rpy="0.0 0.0 0.0" xyz="0.0 0.0 0.0"/>
      <mass value="0.001"/>
      <inertia ixx="1e-09" ixy="0" ixz="0" iyy="1e-09" iyz="0" izz="1e-09"/>
    </inertial>
  </link>
  <joint name="joint_y" type="prismatic">
    <origin rpy="0.0 0.0 0.0" xyz="0.0 0.0 0.0"/>
    <parent link="joint_x_jointbody"/>
    <child link="joint_y_jointbody"/>
    <axis xyz="0 1 0"/>
    <limit effort="100" lower="-10.0" upper="10.0" velocity="1"/>
    <dynamics damping="1.0" friction="1.0"/>
  </joint>
  <transmission name="joint_y_trans">
    <type>transmission_interface/SimpleTransmission</type>
    <joint name="joint_y"/>
    <actuator name="joint_y_motor">
      <mechanicalReduction>1</mechanicalReduction>
    </actuator>
  </transmission>
  <link name="joint_th_jointbody">
    <inertial>
      <origin rpy="0.0 0.0 0.0" xyz="0.0 0.0 0.0"/>
      <mass value="0.001"/>
      <inertia ixx="1e-09" ixy="0" ixz="0" iyy="1e-09" iyz="0" izz="1e-09"/>
    </inertial>
  </link>
  <joint name="joint_th" type="revolute">
    <origin rpy="0.0 0.0 0.0" xyz="0.0 0.0 0.0"/>
    <parent link="joint_y_jointbody"/>
    <child link="joint_th_jointbody"/>
    <axis xyz="0.0 0.0 1.0"/>
    <limit effort="100" lower="-10" upper="10" velocity="1"/>
    <dynamics damping="1.0" friction="1.0"/>
  </joint>
  <transmission name="joint_th_trans">
    <type>transmission_interface/SimpleTransmission</type>
    <joint name="joint_th"/>
    <actuator name="joint_th_motor">
      <mechanicalReduction>1</mechanicalReduction>
    </actuator>
  </transmission>
  <joint name="joint_th_offset" type="fixed">
    <origin rpy="0.0 0.0 0.0" xyz="-0.0 -0.0 -0.0"/>
    <parent link="joint_th_jointbody"/>
    <child link="base"/>
    <axis xyz="0.0 0.0 1.0"/>
    <limit effort="100" lower="0.0" upper="0.0" velocity="100"/>
  </joint>
  <material name="white">
    <color rgba="1 1 1 1"/>
  </material>
  <joint name="arm_base_joint" type="fixed">
    <origin rpy="0 0 0" xyz="0 0 0.33"/>
    <parent link="base"/>
    <child link="arm_base_link"/>
  </joint>
  <link name="arm_base_link">
    <inertial>
      <origin rpy="0 0 0" xyz="-0.000648 -0.000166 0.084487"/>
      <mass value="1.697"/>
      <inertia ixx="0.004622" ixy="9E-06" ixz="6E-05" iyy="0.004495" iyz="9E-06" izz="0.002079"/>
    </inertial>
    <visual>
      <origin rpy="0 0 0" xyz="0 0 0"/>
      <geometry>
        <mesh filename="file:///home/janchen/Documents/ros2/tidybot_ws/install/tidybot_description/share/tidybot_description/meshes/arms/gen3_7dof/base_link.STL"/>
      </geometry>
      <material name="">
        <color rgba="0.75294 0.75294 0.75294 1"/>
      </material>
    </visual>
    <collision>
      <origin rpy="0 0 0" xyz="0 0 0"/>
      <geometry>
        <mesh filename="file:///home/janchen/Documents/ros2/tidybot_ws/install/tidybot_description/share/tidybot_description/meshes/arms/gen3_7dof/base_link.STL"/>
      </geometry>
    </collision>
  </link>
  <gazebo reference="arm_base_link">
    <material>Gazebo/Gray</material>
  </gazebo>
  <link name="shoulder_link">
    <inertial>
      <origin rpy="0 0 0" xyz="-2.3E-05 -0.010364 -0.07336"/>
      <mass value="1.3773"/>
      <inertia ixx="0.00457" ixy="1E-06" ixz="2E-06" iyy="0.004831" iyz="0.000448" izz="0.001409"/>
    </inertial>
    <visual>
      <origin rpy="0 0 0" xyz="0 0 0"/>
      <geometry>
        <mesh filename="file:///home/janchen/Documents/ros2/tidybot_ws/install/tidybot_description/share/tidybot_description/meshes/arms/gen3_7dof/shoulder_link.STL"/>
      </geometry>
      <material name="">
        <color rgba="0.75294 0.75294 0.75294 1"/>
      </material>
    </visual>
    <collision>
      <origin rpy="0 0 0" xyz="0 0 0"/>
      <geometry>
        <mesh filename="file:///home/janchen/Documents/ros2/tidybot_ws/install/tidybot_description/share/tidybot_description/meshes/arms/gen3_7dof/shoulder_link.STL"/>
      </geometry>
    </collision>
  </link>
  <gazebo reference="shoulder_link">
    <material>Gazebo/Gray</material>
  </gazebo>
  <joint name="joint_1" type="continuous">
    <origin rpy="3.1416 2.7629E-18 -4.9305E-36" xyz="0 0 0.15643"/>
    <parent link="arm_base_link"/>
    <child link="shoulder_link"/>
    <axis xyz="0 0 1"/>
    <limit effort="39" velocity="1.3963"/>
  </joint>
  <link name="half_arm_1_link">
    <inertial>
      <origin rpy="0 0 0" xyz="-4.4E-05 -0.09958 -0.013278"/>
      <mass value="1.1636"/>
      <inertia ixx="0.011088" ixy="5E-06" ixz="0" iyy="0.001072" iyz="-0.000691" izz="0.011255"/>
    </inertial>
    <visual>
      <origin rpy="0 0 0" xyz="0 0 0"/>
      <geometry>
        <mesh filename="file:///home/janchen/Documents/ros2/tidybot_ws/install/tidybot_description/share/tidybot_description/meshes/arms/gen3_7dof/half_arm_1_link.STL"/>
      </geometry>
      <material name="">
        <color rgba="0.75294 0.75294 0.75294 1"/>
      </material>
    </visual>
    <collision>
      <origin rpy="0 0 0" xyz="0 0 0"/>
      <geometry>
        <mesh filename="file:///home/janchen/Documents/ros2/tidybot_ws/install/tidybot_description/share/tidybot_description/meshes/arms/gen3_7dof/half_arm_1_link.STL"/>
      </geometry>
    </collision>
  </link>
  <gazebo reference="half_arm_1_link">
    <material>Gazebo/Gray</material>
  </gazebo>
  <joint name="joint_2" type="revolute">
    <origin rpy="1.5708 2.1343E-17 -1.1102E-16" xyz="0 0.005375 -0.12838"/>
    <parent link="shoulder_link"/>
    <child link="half_arm_1_link"/>
    <axis xyz="0 0 1"/>
    <limit effort="39" lower="-2.24" upper="2.24" velocity="1.3963"/>
  </joint>
  <link name="half_arm_2_link">
    <inertial>
      <origin rpy="0 0 0" xyz="-4.4E-05 -0.006641 -0.117892"/>
      <mass value="1.1636"/>
      <inertia ixx="0.010932" ixy="0" ixz="-7E-06" iyy="0.011127" iyz="0.000606" izz="0.001043"/>
    </inertial>
    <visual>
      <origin rpy="0 0 0" xyz="0 0 0"/>
      <geometry>
        <mesh filename="file:///home/janchen/Documents/ros2/tidybot_ws/install/tidybot_description/share/tidybot_description/meshes/arms/gen3_7dof/half_arm_2_link.STL"/>
      </geometry>
      <material name="">
        <color rgba="0.75294 0.75294 0.75294 1"/>
      </material>
    </visual>
    <collision>
      <origin rpy="0 0 0" xyz="0 0 0"/>
      <geometry>
        <mesh filename="file:///home/janchen/Documents/ros2/tidybot_ws/install/tidybot_description/share/tidybot_description/meshes/arms/gen3_7dof/half_arm_2_link.STL"/>
      </geometry>
    </collision>
  </link>
  <gazebo reference="half_arm_2_link">
    <material>Gazebo/Gray</material>
  </gazebo>
  <joint name="joint_3" type="continuous">
    <origin rpy="-1.5708 1.2326E-32 -2.9122E-16" xyz="0 -0.21038 -0.006375"/>
    <parent link="half_arm_1_link"/>
    <child link="half_arm_2_link"/>
    <axis xyz="0 0 1"/>
    <limit effort="39" velocity="1.3963"/>
  </joint>
  <link name="forearm_link">
    <inertial>
      <origin rpy="0 0 0" xyz="-1.8E-05 -0.075478 -0.015006"/>
      <mass value="0.9302"/>
      <inertia ixx="0.008147" ixy="-1E-06" ixz="0" iyy="0.000631" iyz="-0.0005" izz="0.008316"/>
    </inertial>
    <visual>
      <origin rpy="0 0 0" xyz="0 0 0"/>
      <geometry>
        <mesh filename="file:///home/janchen/Documents/ros2/tidybot_ws/install/tidybot_description/share/tidybot_description/meshes/arms/gen3_7dof/forearm_link.STL"/>
      </geometry>
      <material name="">
        <color rgba="0.75294 0.75294 0.75294 1"/>
      </material>
    </visual>
    <collision>
      <origin rpy="0 0 0" xyz="0 0 0"/>
      <geometry>
        <mesh filename="file:///home/janchen/Documents/ros2/tidybot_ws/install/tidybot_description/share/tidybot_description/meshes/arms/gen3_7dof/forearm_link.STL"/>
      </geometry>
    </collision>
  </link>
  <gazebo reference="forearm_link">
    <material>Gazebo/Gray</material>
  </gazebo>
  <joint name="joint_4" type="revolute">
    <origin rpy="1.5708 -6.6954E-17 -1.6653E-16" xyz="0 0.006375 -0.21038"/>
    <parent link="half_arm_2_link"/>
    <child link="forearm_link"/>
    <axis xyz="0 0 1"/>
    <limit effort="39" lower="-2.57" upper="2.57" velocity="1.3963"/>
  </joint>
  <link name="spherical_wrist_1_link">
    <inertial>
      <origin rpy="0 0 0" xyz="1E-06 -0.009432 -0.063883"/>
      <mass value="0.6781"/>
      <inertia ixx="0.001596" ixy="0" ixz="0" iyy="0.001607" iyz="0.000256" izz="0.000399"/>
    </inertial>
    <visual>
      <origin rpy="0 0 0" xyz="0 0 0"/>
      <geometry>
        <mesh filename="file:///home/janchen/Documents/ros2/tidybot_ws/install/tidybot_description/share/tidybot_description/meshes/arms/gen3_7dof/spherical_wrist_1_link.STL"/>
      </geometry>
      <material name="">
        <color rgba="0.75294 0.75294 0.75294 1"/>
      </material>
    </visual>
    <collision>
      <origin rpy="0 0 0" xyz="0 0 0"/>
      <geometry>
        <mesh filename="file:///home/janchen/Documents/ros2/tidybot_ws/install/tidybot_description/share/tidybot_description/meshes/arms/gen3_7dof/spherical_wrist_1_link.STL"/>
      </geometry>
    </collision>
  </link>
  <gazebo reference="spherical_wrist_1_link">
    <material>Gazebo/Gray</material>
  </gazebo>
  <joint name="joint_5" type="continuous">
    <origin rpy="-1.5708 2.2204E-16 -6.373E-17" xyz="0 -0.20843 -0.006375"/>
    <parent link="forearm_link"/>
    <child link="spherical_wrist_1_link"/>
    <axis xyz="0 0 1"/>
    <limit effort="9" velocity="1.2218"/>
  </joint>
  <link name="spherical_wrist_2_link">
    <inertial>
      <origin rpy="0 0 0" xyz="1E-06 -0.045483 -0.00965"/>
      <mass value="0.6781"/>
      <inertia ixx="0.001641" ixy="0" ixz="0" iyy="0.00041" iyz="-0.000278" izz="0.001641"/>
    </inertial>
    <visual>
      <origin rpy="0 0 0" xyz="0 0 0"/>
      <geometry>
        <mesh filename="file:///home/janchen/Documents/ros2/tidybot_ws/install/tidybot_description/share/tidybot_description/meshes/arms/gen3_7dof/spherical_wrist_2_link.STL"/>
      </geometry>
      <material name="">
        <color rgba="0.75294 0.75294 0.75294 1"/>
      </material>
    </visual>
    <collision>
      <origin rpy="0 0 0" xyz="0 0 0"/>
      <geometry>
        <mesh filename="file:///home/janchen/Documents/ros2/tidybot_ws/install/tidybot_description/share/tidybot_description/meshes/arms/gen3_7dof/spherical_wrist_2_link.STL"/>
      </geometry>
    </collision>
  </link>
  <gazebo reference="spherical_wrist_2_link">
    <material>Gazebo/Gray</material>
  </gazebo>
  <joint name="joint_6" type="revolute">
    <origin rpy="1.5708 9.2076E-28 -8.2157E-15" xyz="0 0.00017505 -0.10593"/>
    <parent link="spherical_wrist_1_link"/>
    <child link="spherical_wrist_2_link"/>
    <axis xyz="0 0 1"/>
    <limit effort="9" lower="-2.09" upper="2.09" velocity="1.2218"/>
  </joint>
  <link name="bracelet_link">
    <inertial>
      <origin rpy="0 0 0" xyz="-9.3E-05 0.000132 -0.022905"/>
      <mass value="0.364"/>
      <inertia ixx="0.000214" ixy="0" ixz="1E-06" iyy="0.000223" iyz="-2E-06" izz="0.00024"/>
    </inertial>
    <visual>
      <origin rpy="0 0 0" xyz="0 0 0"/>
      <geometry>
        <mesh filename="file:///home/janchen/Documents/ros2/tidybot_ws/install/tidybot_description/share/tidybot_description/meshes/arms/gen3_7dof/bracelet_no_vision_link.STL"/>
      </geometry>
      <material name="">
        <color rgba="0.75294 0.75294 0.75294 1"/>
      </material>
    </visual>
    <collision>
      <origin rpy="0 0 0" xyz="0 0 0"/>
      <geometry>
        <mesh filename="file:///home/janchen/Documents/ros2/tidybot_ws/install/tidybot_description/share/tidybot_description/meshes/arms/gen3_7dof/bracelet_no_vision_link.STL"/>
      </geometry>
    </collision>
  </link>
  <gazebo reference="bracelet_link">
    <material>Gazebo/Gray</material>
  </gazebo>
  <joint name="joint_7" type="continuous">
    <origin rpy="-1.5708 -5.5511E-17 9.6396E-17" xyz="0 -0.10593 -0.00017505"/>
    <parent link="spherical_wrist_2_link"/>
    <child link="bracelet_link"/>
    <axis xyz="0 0 1"/>
    <limit effort="9" velocity="1.2218"/>
  </joint>
  <link name="end_effector_link"/>
  <joint name="end_effector" type="fixed">
    <origin rpy="3.14159265358979 1.09937075168372E-32 0" xyz="0 0 -0.0615250000000001"/>
    <parent link="bracelet_link"/>
    <child link="end_effector_link"/>
    <axis xyz="0 0 0"/>
  </joint>
  <!-- Tool frame used by the arm -->
  <link name="tool_frame"/>
  <joint name="tool_frame_joint" type="fixed">
    <origin rpy="0 0 1.57079632679" xyz="0 0 0.130"/>
    <parent link="end_effector_link"/>
    <child link="tool_frame"/>
    <axis xyz="0 0 0"/>
  </joint>
  <!-- Gripper description -->
  <joint name="gripper_base_joint" type="fixed">
    <origin rpy="0 0 0" xyz="0 0 0"/>
    <parent link="end_effector_link"/>
    <child link="gripper_base_link"/>
    <axis xyz="0 0 0"/>
  </joint>
  <link name="gripper_base_link">
    <inertial>
      <origin rpy="0 0 0" xyz="4.03E-06 1.08E-05 0.041397"/>
      <mass value="0.1395"/>
      <inertia ixx="0.00011614" ixy="1E-08" ixz="4E-08" iyy="0.00010327" iyz="0" izz="9.707E-05"/>
    </inertial>
    <visual>
      <origin rpy="0 0 0" xyz="0 0 0"/>
      <geometry>
        <mesh filename="file:///home/janchen/Documents/ros2/tidybot_ws/install/tidybot_description/share/tidybot_description/meshes/grippers/gen3_lite_2f/gripper_base_link.STL"/>
      </geometry>
      <material name="">
        <color rgba="0.803 0.824 0.820 1"/>
      </material>
    </visual>
    <!-- Need to be replaced with simplified mesh -->
    <!-- <collision>
        <origin xyz="0 0 0" rpy="0 0 0" />
        <geometry>
          <mesh filename="file://$(find tidybot_description)/meshes/grippers/gen3_lite_2f/gripper_base_link.STL" />
        </geometry>
      </collision> -->
  </link>
  <gazebo reference="gripper_base_link">
    <material>Gazebo/Gray</material>
  </gazebo>
  <link name="right_finger_prox_link">
    <inertial>
      <origin rpy="0 0 0" xyz="0.020257 0.0063483 6.991E-05"/>
      <mass value="0.018385"/>
      <inertia ixx="2.29E-06" ixy="1.43E-06" ixz="0" iyy="4.56E-06" iyz="0" izz="4.77E-06"/>
    </inertial>
    <visual>
      <origin rpy="0 0 0" xyz="0 0 0"/>
      <geometry>
        <mesh filename="file:///home/janchen/Documents/ros2/tidybot_ws/install/tidybot_description/share/tidybot_description/meshes/grippers/gen3_lite_2f/right_finger_prox_link.STL"/>
      </geometry>
      <material name="">
        <color rgba="0.803 0.824 0.820 1"/>
      </material>
    </visual>
    <!-- <collision>
      <origin xyz="0 0 0" rpy="0 0 0" />
      <geometry>
        <mesh filename="file://$(find tidybot_description)/meshes/grippers/gen3_lite_2f/right_finger_prox_link.STL" />
      </geometry>
    </collision> -->
  </link>
  <gazebo reference="right_finger_prox_link">
    <material>Gazebo/Gray</material>
  </gazebo>
  <joint name="right_finger_bottom_joint" type="revolute">
    <origin rpy="0 1.5708 0" xyz="0 -0.030501 0.070003"/>
    <parent link="gripper_base_link"/>
    <child link="right_finger_prox_link"/>
    <axis xyz="0 0 1"/>
    <limit effort="1000" lower="-0.09" upper="0.96" velocity="1000"/>
    <dynamics damping="1.0" friction="1.0"/>
  </joint>
  <transmission name="right_finger_bottom_joint_trans">
    <type>transmission_interface/SimpleTransmission</type>
    <joint name="right_finger_bottom_joint"/>
    <actuator name="right_finger_bottom_joint_motor">
      <mechanicalReduction>1</mechanicalReduction>
    </actuator>
  </transmission>
  <link name="right_finger_dist_link">
    <inertial>
      <origin rpy="0 0 0" xyz="0.018488 0.0011091 0"/>
      <mass value="0.010748"/>
      <inertia ixx="6.3E-07" ixy="3.2E-07" ixz="0" iyy="1.83E-06" iyz="0" izz="1.61E-06"/>
    </inertial>
    <visual>
      <origin rpy="0 0 0" xyz="0 0 0"/>
      <geometry>
        <mesh filename="file:///home/janchen/Documents/ros2/tidybot_ws/install/tidybot_description/share/tidybot_description/meshes/grippers/gen3_lite_2f/right_finger_dist_link.STL"/>
      </geometry>
      <material name="">
        <color rgba="0 0.055 0.525 1"/>
      </material>
    </visual>
    <!-- <collision>
        <origin xyz="0 0 0" rpy="0 0 0" />
        <geometry>
          <mesh filename="file://$(find tidybot_description)/meshes/grippers/gen3_lite_2f/right_finger_dist_link.STL" />
        </geometry>
      </collision> -->
  </link>
  <gazebo reference="right_finger_dist_link">
    <material>Gazebo/Blue</material>
  </gazebo>
  <joint name="right_finger_tip_joint" type="revolute">
    <origin rpy="0 0 0" xyz="-0.045636 0.020423 0"/>
    <parent link="right_finger_prox_link"/>
    <child link="right_finger_dist_link"/>
    <axis xyz="0 0 1"/>
    <limit effort="1000.0" lower="-0.50" upper="0.21" velocity="1000.0"/>
    <!--limit lower="-1.03" upper="0.21" effort="1000" velocity="1000" /-->
    <!-- <mimic joint="${prefix}right_finger_bottom_joint" multiplier="-0.676" offset="0.149" /> -->
    <dynamics damping="1.0" friction="1.0"/>
  </joint>
  <transmission name="right_finger_tip_joint_trans">
    <type>transmission_interface/SimpleTransmission</type>
    <joint name="right_finger_tip_joint"/>
    <actuator name="right_finger_tip_joint_motor">
      <mechanicalReduction>1</mechanicalReduction>
    </actuator>
  </transmission>
  <link name="left_finger_prox_link">
    <inertial>
      <origin rpy="0 0 0" xyz="0.020257 0.0063483 6.99E-05"/>
      <mass value="0.018385"/>
      <inertia ixx="2.29E-06" ixy="1.43E-06" ixz="0" iyy="4.56E-06" iyz="0" izz="4.77E-06"/>
    </inertial>
    <visual>
      <origin rpy="0 0 0" xyz="0 0 0"/>
      <geometry>
        <mesh filename="file:///home/janchen/Documents/ros2/tidybot_ws/install/tidybot_description/share/tidybot_description/meshes/grippers/gen3_lite_2f/left_finger_prox_link.STL"/>
      </geometry>
      <material name="">
        <color rgba="0.803 0.824 0.820 1"/>
      </material>
    </visual>
    <!-- <collision>
        <origin xyz="0 0 0" rpy="0 0 0" />
        <geometry>
          <mesh filename="file://$(find tidybot_description)/meshes/grippers/gen3_lite_2f/left_finger_prox_link.STL" />
        </geometry>
      </collision> -->
  </link>
  <gazebo reference="left_finger_prox_link">
    <material>Gazebo/Gray</material>
  </gazebo>
  <joint name="left_finger_bottom_joint" type="revolute">
    <origin rpy="0 1.5708 0" xyz="0 0.0305 0.070003"/>
    <parent link="gripper_base_link"/>
    <child link="left_finger_prox_link"/>
    <axis xyz="0 0 1"/>
    <limit effort="1000.0" lower="-0.96" upper="0.09" velocity="1000.0"/>
    <!-- <mimic joint="${prefix}right_finger_bottom_joint" multiplier="-1.0" offset="0.0" /> -->
    <dynamics damping="1.0" friction="1.0"/>
  </joint>
  <transmission name="left_finger_bottom_joint_trans">
    <type>transmission_interface/SimpleTransmission</type>
    <joint name="left_finger_bottom_joint"/>
    <actuator name="left_finger_bottom_joint_motor">
      <mechanicalReduction>1</mechanicalReduction>
    </actuator>
  </transmission>
  <link name="left_finger_dist_link">
    <inertial>
      <origin rpy="0 0 0" xyz="-0.018488 0.0011091 0"/>
      <mass value="0.010748"/>
      <inertia ixx="6.3E-07" ixy="3.2E-07" ixz="0" iyy="1.83E-06" iyz="0" izz="1.61E-06"/>
    </inertial>
    <visual>
      <origin rpy="0 0 0" xyz="0 0 0"/>
      <geometry>
        <mesh filename="file:///home/janchen/Documents/ros2/tidybot_ws/install/tidybot_description/share/tidybot_description/meshes/grippers/gen3_lite_2f/left_finger_dist_link.STL"/>
      </geometry>
      <material name="">
        <color rgba="0 0.055 0.525 1"/>
      </material>
    </visual>
    <!-- <collision>
        <origin xyz="0 0 0" rpy="0 0 0" />
        <geometry>
          <mesh filename="file://$(find tidybot_description)/meshes/grippers/gen3_lite_2f/left_finger_dist_link.STL" />
        </geometry>
      </collision> -->
  </link>
  <gazebo reference="left_finger_dist_link">
    <material>Gazebo/Blue</material>
  </gazebo>
  <joint name="left_finger_tip_joint" type="revolute">
    <origin rpy="0 0 0" xyz="-0.045636 -0.020423 6.9901E-05"/>
    <parent link="left_finger_prox_link"/>
    <child link="left_finger_dist_link"/>
    <axis xyz="0 0 -1"/>
    <limit effort="1000.0" lower="-0.50" upper="0.21" velocity="1000.0"/>
    <!--limit lower="-1.03" upper="0.21" effort="1000" velocity="1000" /-->
    <!-- <mimic joint="${prefix}right_finger_bottom_joint" multiplier="-0.676" offset="0.149" /> -->
    <dynamics damping="1.0" friction="1.0"/>
  </joint>
  <transmission name="left_finger_tip_joint_trans">
    <type>transmission_interface/SimpleTransmission</type>
    <joint name="left_finger_tip_joint"/>
    <actuator name="left_finger_tip_joint_motor">
      <mechanicalReduction>1</mechanicalReduction>
    </actuator>
  </transmission>
  <ros2_control name="TidybotSystem" type="system">
    <hardware>
      <plugin>gz_ros2_control/GazeboSimSystem</plugin>
    </hardware>
    <joint name="joint_x">
      <command_interface name="velocity"/>
      <state_interface name="position"/>
      <state_interface name="velocity"/>
      <param name="position_proportional_gain">0.1</param>
    </joint>
    <joint name="joint_x">
      <command_interface name="position"/>
      <state_interface name="position"/>
      <state_interface name="velocity"/>
      <param name="position_proportional_gain">0.1</param>
    </joint>
    <joint name="joint_y">
      <command_interface name="velocity"/>
      <state_interface name="position"/>
      <state_interface name="velocity"/>
      <param name="position_proportional_gain">0.1</param>
    </joint>
    <joint name="joint_y">
      <command_interface name="position"/>
      <state_interface name="position"/>
      <state_interface name="velocity"/>
      <param name="position_proportional_gain">0.1</param>
    </joint>
    <joint name="joint_th">
      <command_interface name="velocity"/>
      <state_interface name="position"/>
      <state_interface name="velocity"/>
      <param name="position_proportional_gain">0.1</param>
    </joint>
    <joint name="joint_th">
      <command_interface name="position"/>
      <state_interface name="position"/>
      <state_interface name="velocity"/>
      <param name="position_proportional_gain">0.1</param>
    </joint>
    <joint name="joint_1">
      <command_interface name="position"/>
      <state_interface name="position"/>
      <state_interface name="velocity"/>
      <param name="position_proportional_gain">0.1</param>
    </joint>
    <joint name="joint_2">
      <command_interface name="position"/>
      <state_interface name="position"/>
      <state_interface name="velocity"/>
      <param name="position_proportional_gain">0.1</param>
    </joint>
    <joint name="joint_3">
      <command_interface name="position"/>
      <state_interface name="position"/>
      <state_interface name="velocity"/>
      <param name="position_proportional_gain">0.1</param>
    </joint>
    <joint name="joint_4">
      <command_interface name="position"/>
      <state_interface name="position"/>
      <state_interface name="velocity"/>
      <param name="position_proportional_gain">0.1</param>
    </joint>
    <joint name="joint_5">
      <command_interface name="position"/>
      <state_interface name="position"/>
      <state_interface name="velocity"/>
      <param name="position_proportional_gain">0.1</param>
    </joint>
    <joint name="joint_6">
      <command_interface name="position"/>
      <state_interface name="position"/>
      <state_interface name="velocity"/>
      <param name="position_proportional_gain">0.1</param>
    </joint>
    <joint name="joint_7">
      <command_interface name="position"/>
      <state_interface name="position"/>
      <state_interface name="velocity"/>
      <param name="position_proportional_gain">0.1</param>
    </joint>
    <joint name="right_finger_bottom_joint">
      <command_interface name="position"/>
      <state_interface name="position"/>
      <state_interface name="velocity"/>
      <param name="position_proportional_gain">0.1</param>
    </joint>
    <joint name="right_finger_tip_joint">
      <command_interface name="position"/>
      <state_interface name="position"/>
      <state_interface name="velocity"/>
      <param name="position_proportional_gain">0.1</param>
    </joint>
    <joint name="left_finger_bottom_joint">
      <command_interface name="position"/>
      <state_interface name="position"/>
      <state_interface name="velocity"/>
      <param name="position_proportional_gain">0.1</param>
    </joint>
    <joint name="left_finger_tip_joint">
      <command_interface name="position"/>
      <state_interface name="position"/>
      <state_interface name="velocity"/>
      <param name="position_proportional_gain">0.1</param>
    </joint>
  </ros2_control>
  <gazebo>
    <plugin filename="gz_ros2_control-system" name="gz_ros2_control::GazeboSimROS2ControlPlugin">
      <parameters>/home/janchen/Documents/ros2/tidybot_ws/install/tidybot_description/share/tidybot_description/config/tidybot_controllers.yaml</parameters>
      <!-- <robot_description_param>robot_description</robot_description_param> -->
    </plugin>
    <!-- <self_collide>true</self_collide> -->
  </gazebo>
  <!-- <gazebo>
    <plugin filename="ignition-gazebo-joint-state-publisher-system" name="ignition::gazebo::systems::JointStatePublisher"/>

    <plugin
        filename="ignition-gazebo-pose-publisher-system"
        name="ignition::gazebo::systems::PosePublisher">
        <publish_link_pose>true</publish_link_pose>

        <use_pose_vector_msg>true</use_pose_vector_msg>
    </plugin>

  </gazebo> -->
  <transmission name=" joint_1_trans">
    <type>transmission_interface/SimpleTransmission</type>
    <actuator name=" joint_1_motor"/>
    <joint name=" joint_1"/>
    <mechanicalReduction>1</mechanicalReduction>
  </transmission>
  <transmission name=" joint_2_trans">
    <type>transmission_interface/SimpleTransmission</type>
    <actuator name=" joint_2_motor"/>
    <joint name=" joint_2"/>
    <mechanicalReduction>1</mechanicalReduction>
  </transmission>
  <transmission name=" joint_3_trans">
    <type>transmission_interface/SimpleTransmission</type>
    <actuator name=" joint_3_motor"/>
    <joint name=" joint_3"/>
    <mechanicalReduction>1</mechanicalReduction>
  </transmission>
  <transmission name=" joint_4_trans">
    <type>transmission_interface/SimpleTransmission</type>
    <actuator name=" joint_4_motor"/>
    <joint name=" joint_4"/>
    <mechanicalReduction>1</mechanicalReduction>
  </transmission>
  <transmission name=" joint_5_trans">
    <type>transmission_interface/SimpleTransmission</type>
    <actuator name=" joint_5_motor"/>
    <joint name=" joint_5"/>
    <mechanicalReduction>1</mechanicalReduction>
  </transmission>
  <transmission name=" joint_6_trans">
    <type>transmission_interface/SimpleTransmission</type>
    <actuator name=" joint_6_motor"/>
    <joint name=" joint_6"/>
    <mechanicalReduction>1</mechanicalReduction>
  </transmission>
  <transmission name=" joint_7_trans">
    <type>transmission_interface/SimpleTransmission</type>
    <actuator name=" joint_7_motor"/>
    <joint name=" joint_7"/>
    <mechanicalReduction>1</mechanicalReduction>
  </transmission>
</robot>
