<?xml version="1.0" ?>
<!-- =================================================================================== -->
<!-- |    This document was autogenerated by xacro from src/tidybot_description/urdf/tidybot.xacro | -->
<!-- |    EDITING THIS FILE BY HAND IS NOT RECOMMENDED                                 | -->
<!-- =================================================================================== -->
<robot name="tidybot">
  <!-- <xacro:load_base prefix=""/> -->
  <link name="world"/>
  <link name="base">
    <inertial>
      <origin rpy="0 0 0" xyz="0 0 0"/>
      <mass value="34"/>
      <inertia ixx="1e-09" ixy="0" ixz="0" iyy="1e-09" iyz="0" izz="1e-09"/>
    </inertial>
    <!-- Part kinova -->
    <visual>
      <origin rpy="0 -0 0" xyz="-0.3066 0.064 0.085"/>
      <geometry>
        <mesh filename="file:///home/yuandi/tidybot_platform/install/tidybot_description/share/tidybot_description/meshes/base/tidybot++/Kinova.stl"/>
      </geometry>
      <material name="kinova_material">
        <color rgba="0.917647 0.917647 0.917647 1"/>
      </material>
    </visual>
    <collision>
      <origin rpy="0 -0 0" xyz="-0.3066 0.064 0.085"/>
      <geometry>
        <mesh filename="file:///home/yuandi/tidybot_platform/install/tidybot_description/share/tidybot_description/meshes/base/tidybot++/Kinova.stl"/>
      </geometry>
    </collision>
  </link>
  <link name="joint_x_jointbody">
    <inertial>
      <origin rpy="0.0 0.0 0.0" xyz="0.0 0.0 0.0"/>
      <mass value="0.001"/>
      <inertia ixx="1e-09" ixy="0" ixz="0" iyy="1e-09" iyz="0" izz="1e-09"/>
    </inertial>
  </link>
  <joint name="joint_x" type="prismatic">
    <origin rpy="0.0 0.0 0.0" xyz="0.0 0.0 0.0"/>
    <parent link="world"/>
    <child link="joint_x_jointbody"/>
    <axis xyz="1 0 0"/>
    <limit effort="100" lower="-10.0" upper="10.0" velocity="1"/>
    <dynamics damping="1.0" friction="1.0"/>
  </joint>
  <link name="joint_y_jointbody">
    <inertial>
      <origin rpy="0.0 0.0 0.0" xyz="0.0 0.0 0.0"/>
      <mass value="0.001"/>
      <inertia ixx="1e-09" ixy="0" ixz="0" iyy="1e-09" iyz="0" izz="1e-09"/>
    </inertial>
  </link>
  <joint name="joint_y" type="prismatic">
    <origin rpy="0.0 0.0 0.0" xyz="0.0 0.0 0.0"/>
    <parent link="joint_x_jointbody"/>
    <child link="joint_y_jointbody"/>
    <axis xyz="0 1 0"/>
    <limit effort="100" lower="-10.0" upper="10.0" velocity="1"/>
    <dynamics damping="1.0" friction="1.0"/>
  </joint>
  <link name="joint_th_jointbody">
    <inertial>
      <origin rpy="0.0 0.0 0.0" xyz="0.0 0.0 0.0"/>
      <mass value="0.001"/>
      <inertia ixx="1e-09" ixy="0" ixz="0" iyy="1e-09" iyz="0" izz="1e-09"/>
    </inertial>
  </link>
  <joint name="joint_th" type="revolute">
    <origin rpy="0.0 0.0 0.0" xyz="0.0 0.0 0.0"/>
    <parent link="joint_y_jointbody"/>
    <child link="joint_th_jointbody"/>
    <axis xyz="0.0 0.0 1.0"/>
    <limit effort="100" lower="-10" upper="10" velocity="1"/>
    <dynamics damping="1.0" friction="1.0"/>
  </joint>
  <joint name="joint_th_offset" type="fixed">
    <origin rpy="0.0 0.0 0.0" xyz="-0.0 -0.0 -0.0"/>
    <parent link="joint_th_jointbody"/>
    <child link="base"/>
    <axis xyz="0.0 0.0 1.0"/>
    <limit effort="100" lower="0.0" upper="0.0" velocity="100"/>
  </joint>
  <material name="white">
    <color rgba="1 1 1 1"/>
  </material>
  <joint name="arm_base_joint" type="fixed">
    <origin rpy="0 0 0" xyz="0.12 3.76986e-15 0.374775"/>
    <parent link="base"/>
    <child link="arm_base_link"/>
  </joint>
  <link name="arm_base_link">
    <inertial>
      <origin rpy="0 0 0" xyz="-0.000648 -0.000166 0.084487"/>
      <mass value="1.697"/>
      <inertia ixx="0.004622" ixy="9E-06" ixz="6E-05" iyy="0.004495" iyz="9E-06" izz="0.002079"/>
    </inertial>
    <visual>
      <origin rpy="0 0 0" xyz="0 0 0"/>
      <geometry>
        <mesh filename="file:///home/yuandi/tidybot_platform/install/tidybot_description/share/tidybot_description/meshes/arms/gen3_7dof/base_link.STL"/>
      </geometry>
      <material name="">
        <color rgba="0.75294 0.75294 0.75294 1"/>
      </material>
    </visual>
    <collision>
      <origin rpy="0 0 0" xyz="0 0 0"/>
      <geometry>
        <mesh filename="file:///home/yuandi/tidybot_platform/install/tidybot_description/share/tidybot_description/meshes/arms/gen3_7dof/base_link.STL"/>
      </geometry>
    </collision>
  </link>
  <gazebo reference="arm_base_link">
    <material>Gazebo/Gray</material>
  </gazebo>
  <link name="shoulder_link">
    <inertial>
      <origin rpy="0 0 0" xyz="-2.3E-05 -0.010364 -0.07336"/>
      <mass value="1.3773"/>
      <inertia ixx="0.00457" ixy="1E-06" ixz="2E-06" iyy="0.004831" iyz="0.000448" izz="0.001409"/>
    </inertial>
    <visual>
      <origin rpy="0 0 0" xyz="0 0 0"/>
      <geometry>
        <mesh filename="file:///home/yuandi/tidybot_platform/install/tidybot_description/share/tidybot_description/meshes/arms/gen3_7dof/shoulder_link.STL"/>
      </geometry>
      <material name="">
        <color rgba="0.75294 0.75294 0.75294 1"/>
      </material>
    </visual>
    <collision>
      <origin rpy="0 0 0" xyz="0 0 0"/>
      <geometry>
        <mesh filename="file:///home/yuandi/tidybot_platform/install/tidybot_description/share/tidybot_description/meshes/arms/gen3_7dof/shoulder_link.STL"/>
      </geometry>
    </collision>
  </link>
  <gazebo reference="shoulder_link">
    <material>Gazebo/Gray</material>
  </gazebo>
  <joint name="joint_1" type="continuous">
    <origin rpy="3.1416 2.7629E-18 -4.9305E-36" xyz="0 0 0.15643"/>
    <parent link="arm_base_link"/>
    <child link="shoulder_link"/>
    <axis xyz="0 0 1"/>
    <limit effort="39" velocity="1.3963"/>
  </joint>
  <link name="half_arm_1_link">
    <inertial>
      <origin rpy="0 0 0" xyz="-4.4E-05 -0.09958 -0.013278"/>
      <mass value="1.1636"/>
      <inertia ixx="0.011088" ixy="5E-06" ixz="0" iyy="0.001072" iyz="-0.000691" izz="0.011255"/>
    </inertial>
    <visual>
      <origin rpy="0 0 0" xyz="0 0 0"/>
      <geometry>
        <mesh filename="file:///home/yuandi/tidybot_platform/install/tidybot_description/share/tidybot_description/meshes/arms/gen3_7dof/half_arm_1_link.STL"/>
      </geometry>
      <material name="">
        <color rgba="0.75294 0.75294 0.75294 1"/>
      </material>
    </visual>
    <collision>
      <origin rpy="0 0 0" xyz="0 0 0"/>
      <geometry>
        <mesh filename="file:///home/yuandi/tidybot_platform/install/tidybot_description/share/tidybot_description/meshes/arms/gen3_7dof/half_arm_1_link.STL"/>
      </geometry>
    </collision>
  </link>
  <gazebo reference="half_arm_1_link">
    <material>Gazebo/Gray</material>
  </gazebo>
  <joint name="joint_2" type="revolute">
    <origin rpy="1.5708 2.1343E-17 -1.1102E-16" xyz="0 0.005375 -0.12838"/>
    <parent link="shoulder_link"/>
    <child link="half_arm_1_link"/>
    <axis xyz="0 0 1"/>
    <limit effort="39" lower="-2.24" upper="2.24" velocity="1.3963"/>
  </joint>
  <link name="half_arm_2_link">
    <inertial>
      <origin rpy="0 0 0" xyz="-4.4E-05 -0.006641 -0.117892"/>
      <mass value="1.1636"/>
      <inertia ixx="0.010932" ixy="0" ixz="-7E-06" iyy="0.011127" iyz="0.000606" izz="0.001043"/>
    </inertial>
    <visual>
      <origin rpy="0 0 0" xyz="0 0 0"/>
      <geometry>
        <mesh filename="file:///home/yuandi/tidybot_platform/install/tidybot_description/share/tidybot_description/meshes/arms/gen3_7dof/half_arm_2_link.STL"/>
      </geometry>
      <material name="">
        <color rgba="0.75294 0.75294 0.75294 1"/>
      </material>
    </visual>
    <collision>
      <origin rpy="0 0 0" xyz="0 0 0"/>
      <geometry>
        <mesh filename="file:///home/yuandi/tidybot_platform/install/tidybot_description/share/tidybot_description/meshes/arms/gen3_7dof/half_arm_2_link.STL"/>
      </geometry>
    </collision>
  </link>
  <gazebo reference="half_arm_2_link">
    <material>Gazebo/Gray</material>
  </gazebo>
  <joint name="joint_3" type="continuous">
    <origin rpy="-1.5708 1.2326E-32 -2.9122E-16" xyz="0 -0.21038 -0.006375"/>
    <parent link="half_arm_1_link"/>
    <child link="half_arm_2_link"/>
    <axis xyz="0 0 1"/>
    <limit effort="39" velocity="1.3963"/>
  </joint>
  <link name="forearm_link">
    <inertial>
      <origin rpy="0 0 0" xyz="-1.8E-05 -0.075478 -0.015006"/>
      <mass value="0.9302"/>
      <inertia ixx="0.008147" ixy="-1E-06" ixz="0" iyy="0.000631" iyz="-0.0005" izz="0.008316"/>
    </inertial>
    <visual>
      <origin rpy="0 0 0" xyz="0 0 0"/>
      <geometry>
        <mesh filename="file:///home/yuandi/tidybot_platform/install/tidybot_description/share/tidybot_description/meshes/arms/gen3_7dof/forearm_link.STL"/>
      </geometry>
      <material name="">
        <color rgba="0.75294 0.75294 0.75294 1"/>
      </material>
    </visual>
    <collision>
      <origin rpy="0 0 0" xyz="0 0 0"/>
      <geometry>
        <mesh filename="file:///home/yuandi/tidybot_platform/install/tidybot_description/share/tidybot_description/meshes/arms/gen3_7dof/forearm_link.STL"/>
      </geometry>
    </collision>
  </link>
  <gazebo reference="forearm_link">
    <material>Gazebo/Gray</material>
  </gazebo>
  <joint name="joint_4" type="revolute">
    <origin rpy="1.5708 -6.6954E-17 -1.6653E-16" xyz="0 0.006375 -0.21038"/>
    <parent link="half_arm_2_link"/>
    <child link="forearm_link"/>
    <axis xyz="0 0 1"/>
    <limit effort="39" lower="-2.57" upper="2.57" velocity="1.3963"/>
  </joint>
  <link name="spherical_wrist_1_link">
    <inertial>
      <origin rpy="0 0 0" xyz="1E-06 -0.009432 -0.063883"/>
      <mass value="0.6781"/>
      <inertia ixx="0.001596" ixy="0" ixz="0" iyy="0.001607" iyz="0.000256" izz="0.000399"/>
    </inertial>
    <visual>
      <origin rpy="0 0 0" xyz="0 0 0"/>
      <geometry>
        <mesh filename="file:///home/yuandi/tidybot_platform/install/tidybot_description/share/tidybot_description/meshes/arms/gen3_7dof/spherical_wrist_1_link.STL"/>
      </geometry>
      <material name="">
        <color rgba="0.75294 0.75294 0.75294 1"/>
      </material>
    </visual>
    <collision>
      <origin rpy="0 0 0" xyz="0 0 0"/>
      <geometry>
        <mesh filename="file:///home/yuandi/tidybot_platform/install/tidybot_description/share/tidybot_description/meshes/arms/gen3_7dof/spherical_wrist_1_link.STL"/>
      </geometry>
    </collision>
  </link>
  <gazebo reference="spherical_wrist_1_link">
    <material>Gazebo/Gray</material>
  </gazebo>
  <joint name="joint_5" type="continuous">
    <origin rpy="-1.5708 2.2204E-16 -6.373E-17" xyz="0 -0.20843 -0.006375"/>
    <parent link="forearm_link"/>
    <child link="spherical_wrist_1_link"/>
    <axis xyz="0 0 1"/>
    <limit effort="9" velocity="1.2218"/>
  </joint>
  <link name="spherical_wrist_2_link">
    <inertial>
      <origin rpy="0 0 0" xyz="1E-06 -0.045483 -0.00965"/>
      <mass value="0.6781"/>
      <inertia ixx="0.001641" ixy="0" ixz="0" iyy="0.00041" iyz="-0.000278" izz="0.001641"/>
    </inertial>
    <visual>
      <origin rpy="0 0 0" xyz="0 0 0"/>
      <geometry>
        <mesh filename="file:///home/yuandi/tidybot_platform/install/tidybot_description/share/tidybot_description/meshes/arms/gen3_7dof/spherical_wrist_2_link.STL"/>
      </geometry>
      <material name="">
        <color rgba="0.75294 0.75294 0.75294 1"/>
      </material>
    </visual>
    <collision>
      <origin rpy="0 0 0" xyz="0 0 0"/>
      <geometry>
        <mesh filename="file:///home/yuandi/tidybot_platform/install/tidybot_description/share/tidybot_description/meshes/arms/gen3_7dof/spherical_wrist_2_link.STL"/>
      </geometry>
    </collision>
  </link>
  <gazebo reference="spherical_wrist_2_link">
    <material>Gazebo/Gray</material>
  </gazebo>
  <joint name="joint_6" type="revolute">
    <origin rpy="1.5708 9.2076E-28 -8.2157E-15" xyz="0 0.00017505 -0.10593"/>
    <parent link="spherical_wrist_1_link"/>
    <child link="spherical_wrist_2_link"/>
    <axis xyz="0 0 1"/>
    <limit effort="9" lower="-2.09" upper="2.09" velocity="1.2218"/>
  </joint>
  <link name="bracelet_link">
    <inertial>
      <origin rpy="0 0 0" xyz="0.000281 0.011402 -0.029798"/>
      <mass value="0.5"/>
      <inertia ixx="0.000587" ixy="3E-06" ixz="3E-06" iyy="0.000369" iyz="-0.000118" izz="0.000609"/>
    </inertial>
    <visual>
      <origin rpy="0 0 0" xyz="0 0 0"/>
      <geometry>
        <mesh filename="file:///home/yuandi/tidybot_platform/install/tidybot_description/share/tidybot_description/meshes/arms/gen3_7dof/bracelet_with_vision_link.STL"/>
      </geometry>
      <material name="">
        <color rgba="0.75294 0.75294 0.75294 1"/>
      </material>
    </visual>
    <collision>
      <origin rpy="0 0 0" xyz="0 0 0"/>
      <geometry>
        <mesh filename="file:///home/yuandi/tidybot_platform/install/tidybot_description/share/tidybot_description/meshes/arms/gen3_7dof/bracelet_with_vision_link.STL"/>
      </geometry>
    </collision>
  </link>
  <gazebo reference="bracelet_link">
    <material>Gazebo/Gray</material>
  </gazebo>
  <joint name="joint_7" type="continuous">
    <origin rpy="-1.5708 -5.5511E-17 9.6396E-17" xyz="0 -0.10593 -0.00017505"/>
    <parent link="spherical_wrist_2_link"/>
    <child link="bracelet_link"/>
    <axis xyz="0 0 1"/>
    <limit effort="9" velocity="1.2218"/>
  </joint>
  <link name="end_effector_link"/>
  <joint name="end_effector" type="fixed">
    <origin rpy="3.14159265358979 1.09937075168372E-32 0" xyz="0 0 -0.0615250000000001"/>
    <parent link="bracelet_link"/>
    <child link="end_effector_link"/>
    <axis xyz="0 0 0"/>
  </joint>
  <link name="camera_link"/>
  <joint name="camera_module" type="fixed">
    <origin rpy="3.14159265358979 3.14159265358979 0" xyz="0 0.05639 -0.00305"/>
    <parent link="end_effector_link"/>
    <child link="camera_link"/>
  </joint>
  <link name="camera_depth_frame"/>
  <joint name="depth_module" type="fixed">
    <origin rpy="3.14159265358979 3.14159265358979 0" xyz="0.0275 0.066 -0.00305"/>
    <parent link="end_effector_link"/>
    <child link="camera_depth_frame"/>
  </joint>
  <link name="camera_color_frame"/>
  <joint name="color_module" type="fixed">
    <origin rpy="3.14159265358979 3.14159265358979 0" xyz="0 0.05639 -0.00305"/>
    <parent link="end_effector_link"/>
    <child link="camera_color_frame"/>
  </joint>
  <!-- This line was removed by Kinova because we replaced the transmission file with our own 
    <xacro:include filename="$(find robotiq_2f_85_gripper_visualization)/urdf/robotiq_arg2f_transmission.xacro" /> -->
  <!-- Tool frame used by the arm -->
  <link name="tool_frame"/>
  <joint name="tool_frame_joint" type="fixed">
    <origin rpy="0 0 0" xyz="0 0 0.120"/>
    <parent link="end_effector_link"/>
    <child link="tool_frame"/>
    <axis xyz="0 0 0"/>
  </joint>
  <!-- This joint was added by Kinova -->
  <joint name="gripper_base_joint" type="fixed">
    <parent link="end_effector_link"/>
    <child link="robotiq_arg2f_base_link"/>
    <origin rpy="0.0 0.0 1.57" xyz="0.0 0.0 0.0"/>
  </joint>
  <link name="robotiq_arg2f_base_link">
    <inertial>
      <origin rpy="0 0 0" xyz="8.625E-08 -4.6583E-06 0.03145"/>
      <mass value="0.22652"/>
      <inertia ixx="0.00020005" ixy="-4.2442E-10" ixz="-2.9069E-10" iyy="0.00017832" iyz="-3.4402E-08" izz="0.00013478"/>
    </inertial>
    <visual>
      <origin rpy="0 0 0" xyz="0 0 0"/>
      <geometry>
        <!-- The DAE file doesn't show well in Gazebo so we're using the STL instead -->
        <!-- <mesh filename="file://$(find simulation)/meshes/grippers/robotiq_2f_85/meshes/visual/robotiq_arg2f_85_base_link.dae" scale="0.001 0.001 0.001"/> -->
        <mesh filename="file:///home/yuandi/tidybot_platform/install/tidybot_description/share/tidybot_description/meshes/grippers/robotiq_2f_85/collision/robotiq_arg2f_base_link.stl"/>
      </geometry>
      <material name="">
        <color rgba="0.1 0.1 0.1 1"/>
      </material>
    </visual>
    <collision>
      <origin rpy="0 0 0" xyz="0 0 0"/>
      <geometry>
        <mesh filename="file:///home/yuandi/tidybot_platform/install/tidybot_description/share/tidybot_description/meshes/grippers/robotiq_2f_85/collision/robotiq_arg2f_base_link.stl"/>
      </geometry>
    </collision>
  </link>
  <gazebo reference="robotiq_arg2f_base_link">
    <material>Gazebo/Black</material>
  </gazebo>
  <link name="left_outer_knuckle">
    <inertial>
      <origin rpy="0 0 0" xyz="-0.000200000000003065 0.0199435877845359 0.0292245259211331"/>
      <mass value="0.00853198276973456"/>
      <inertia ixx="2.89328108496468E-06" ixy="-1.57935047237397E-19" ixz="-1.93980378593255E-19" iyy="1.86719750325683E-06" iyz="-1.21858577871576E-06" izz="1.21905238907251E-06"/>
    </inertial>
    <visual>
      <origin rpy="0 0 0" xyz="0 0 0"/>
      <geometry>
        <mesh filename="file:///home/yuandi/tidybot_platform/install/tidybot_description/share/tidybot_description/meshes/grippers/robotiq_2f_85/visual/robotiq_arg2f_85_outer_knuckle.dae" scale="0.001 0.001 0.001"/>
      </geometry>
      <material name="">
        <color rgba="0.792156862745098 0.819607843137255 0.933333333333333 1"/>
      </material>
    </visual>
    <collision>
      <origin rpy="0 0 0" xyz="0 0 0"/>
      <geometry>
        <mesh filename="file:///home/yuandi/tidybot_platform/install/tidybot_description/share/tidybot_description/meshes/grippers/robotiq_2f_85/collision/robotiq_arg2f_85_outer_knuckle.dae" scale="0.001 0.001 0.001"/>
      </geometry>
    </collision>
  </link>
  <link name="left_outer_finger">
    <inertial>
      <origin rpy="0 0 0" xyz="0.00030115855001899 0.0373907951953854 -0.0208027427000385"/>
      <mass value="0.022614240507152"/>
      <inertia ixx="1.52518312458174E-05" ixy="9.76583423954399E-10" ixz="-5.43838577022588E-10" iyy="6.17694243867776E-06" iyz="6.78636130740228E-06" izz="1.16494917907219E-05"/>
    </inertial>
    <visual>
      <origin rpy="0 0 0" xyz="0 0 0"/>
      <geometry>
        <mesh filename="file:///home/yuandi/tidybot_platform/install/tidybot_description/share/tidybot_description/meshes/grippers/robotiq_2f_85/visual/robotiq_arg2f_85_outer_finger.dae" scale="0.001 0.001 0.001"/>
      </geometry>
      <material name="">
        <color rgba="0.1 0.1 0.1 1"/>
      </material>
    </visual>
    <collision>
      <origin rpy="0 0 0" xyz="0 0 0"/>
      <geometry>
        <mesh filename="file:///home/yuandi/tidybot_platform/install/tidybot_description/share/tidybot_description/meshes/grippers/robotiq_2f_85/collision/robotiq_arg2f_85_outer_finger.dae" scale="0.001 0.001 0.001"/>
      </geometry>
    </collision>
  </link>
  <link name="left_inner_finger">
    <inertial>
      <origin rpy="0 0 0" xyz="0.000299999999999317 0.0160078233491243 -0.0136945669206257"/>
      <mass value="0.0104003125914103"/>
      <inertia ixx="2.71909453810972E-06" ixy="1.35402465472579E-21" ixz="-7.1817349065269E-22" iyy="7.69100314106116E-07" iyz="6.74715432769696E-07" izz="2.30315190420171E-06"/>
    </inertial>
    <visual>
      <origin rpy="0 0 0" xyz="0 0 0"/>
      <geometry>
        <mesh filename="file:///home/yuandi/tidybot_platform/install/tidybot_description/share/tidybot_description/meshes/grippers/robotiq_2f_85/visual/robotiq_arg2f_85_inner_finger.dae" scale="0.001 0.001 0.001"/>
      </geometry>
      <material name="">
        <color rgba="0.1 0.1 0.1 1"/>
      </material>
    </visual>
    <collision>
      <origin rpy="0 0 0" xyz="0 0 0"/>
      <geometry>
        <mesh filename="file:///home/yuandi/tidybot_platform/install/tidybot_description/share/tidybot_description/meshes/grippers/robotiq_2f_85/collision/robotiq_arg2f_85_inner_finger.dae" scale="0.001 0.001 0.001"/>
      </geometry>
    </collision>
  </link>
  <link name="left_inner_finger_pad">
    <visual>
      <origin rpy="0 0 0" xyz="0 0 0"/>
      <geometry>
        <box size="0.022 0.00635 0.0375"/>
      </geometry>
      <material name="">
        <color rgba="0.9 0.9 0.9 1"/>
      </material>
    </visual>
    <collision>
      <origin rpy="0 0 0" xyz="0 0 0"/>
      <geometry>
        <box size="0.022 0.00635 0.0375"/>
      </geometry>
      <material name="">
        <color rgba="0.9 0.0 0.0 1"/>
      </material>
    </collision>
  </link>
  <link name="left_inner_knuckle">
    <inertial>
      <origin rpy="0 0 0" xyz="0.000123011831763771 0.0507850843201817 0.00103968640075166"/>
      <mass value="0.0271177346495152"/>
      <inertia ixx="2.61910379223783E-05" ixy="-2.43616858946494E-07" ixz="-6.37789906117123E-09" iyy="2.8270243746167E-06" iyz="-5.37200748039765E-07" izz="2.83695868220296E-05"/>
    </inertial>
    <visual>
      <origin rpy="0 0 0" xyz="0 0 0"/>
      <geometry>
        <mesh filename="file:///home/yuandi/tidybot_platform/install/tidybot_description/share/tidybot_description/meshes/grippers/robotiq_2f_85/visual/robotiq_arg2f_85_inner_knuckle.dae" scale="0.001 0.001 0.001"/>
      </geometry>
      <material name="">
        <color rgba="0.1 0.1 0.1 1"/>
      </material>
    </visual>
    <collision>
      <origin rpy="0 0 0" xyz="0 0 0"/>
      <geometry>
        <mesh filename="file:///home/yuandi/tidybot_platform/install/tidybot_description/share/tidybot_description/meshes/grippers/robotiq_2f_85/collision/robotiq_arg2f_85_inner_knuckle.dae" scale="0.001 0.001 0.001"/>
      </geometry>
    </collision>
  </link>
  <link name="right_outer_knuckle">
    <inertial>
      <origin rpy="0 0 0" xyz="-0.000200000000003065 0.0199435877845359 0.0292245259211331"/>
      <mass value="0.00853198276973456"/>
      <inertia ixx="2.89328108496468E-06" ixy="-1.57935047237397E-19" ixz="-1.93980378593255E-19" iyy="1.86719750325683E-06" iyz="-1.21858577871576E-06" izz="1.21905238907251E-06"/>
    </inertial>
    <visual>
      <origin rpy="0 0 0" xyz="0 0 0"/>
      <geometry>
        <mesh filename="file:///home/yuandi/tidybot_platform/install/tidybot_description/share/tidybot_description/meshes/grippers/robotiq_2f_85/visual/robotiq_arg2f_85_outer_knuckle.dae" scale="0.001 0.001 0.001"/>
      </geometry>
      <material name="">
        <color rgba="0.792156862745098 0.819607843137255 0.933333333333333 1"/>
      </material>
    </visual>
    <collision>
      <origin rpy="0 0 0" xyz="0 0 0"/>
      <geometry>
        <mesh filename="file:///home/yuandi/tidybot_platform/install/tidybot_description/share/tidybot_description/meshes/grippers/robotiq_2f_85/collision/robotiq_arg2f_85_outer_knuckle.dae" scale="0.001 0.001 0.001"/>
      </geometry>
    </collision>
  </link>
  <link name="right_outer_finger">
    <inertial>
      <origin rpy="0 0 0" xyz="0.00030115855001899 0.0373907951953854 -0.0208027427000385"/>
      <mass value="0.022614240507152"/>
      <inertia ixx="1.52518312458174E-05" ixy="9.76583423954399E-10" ixz="-5.43838577022588E-10" iyy="6.17694243867776E-06" iyz="6.78636130740228E-06" izz="1.16494917907219E-05"/>
    </inertial>
    <visual>
      <origin rpy="0 0 0" xyz="0 0 0"/>
      <geometry>
        <mesh filename="file:///home/yuandi/tidybot_platform/install/tidybot_description/share/tidybot_description/meshes/grippers/robotiq_2f_85/visual/robotiq_arg2f_85_outer_finger.dae" scale="0.001 0.001 0.001"/>
      </geometry>
      <material name="">
        <color rgba="0.1 0.1 0.1 1"/>
      </material>
    </visual>
    <collision>
      <origin rpy="0 0 0" xyz="0 0 0"/>
      <geometry>
        <mesh filename="file:///home/yuandi/tidybot_platform/install/tidybot_description/share/tidybot_description/meshes/grippers/robotiq_2f_85/collision/robotiq_arg2f_85_outer_finger.dae" scale="0.001 0.001 0.001"/>
      </geometry>
    </collision>
  </link>
  <link name="right_inner_finger">
    <inertial>
      <origin rpy="0 0 0" xyz="0.000299999999999317 0.0160078233491243 -0.0136945669206257"/>
      <mass value="0.0104003125914103"/>
      <inertia ixx="2.71909453810972E-06" ixy="1.35402465472579E-21" ixz="-7.1817349065269E-22" iyy="7.69100314106116E-07" iyz="6.74715432769696E-07" izz="2.30315190420171E-06"/>
    </inertial>
    <visual>
      <origin rpy="0 0 0" xyz="0 0 0"/>
      <geometry>
        <mesh filename="file:///home/yuandi/tidybot_platform/install/tidybot_description/share/tidybot_description/meshes/grippers/robotiq_2f_85/visual/robotiq_arg2f_85_inner_finger.dae" scale="0.001 0.001 0.001"/>
      </geometry>
      <material name="">
        <color rgba="0.1 0.1 0.1 1"/>
      </material>
    </visual>
    <collision>
      <origin rpy="0 0 0" xyz="0 0 0"/>
      <geometry>
        <mesh filename="file:///home/yuandi/tidybot_platform/install/tidybot_description/share/tidybot_description/meshes/grippers/robotiq_2f_85/collision/robotiq_arg2f_85_inner_finger.dae" scale="0.001 0.001 0.001"/>
      </geometry>
    </collision>
  </link>
  <link name="right_inner_finger_pad">
    <visual>
      <origin rpy="0 0 0" xyz="0 0 0"/>
      <geometry>
        <box size="0.022 0.00635 0.0375"/>
      </geometry>
      <material name="">
        <color rgba="0.9 0.9 0.9 1"/>
      </material>
    </visual>
    <collision>
      <origin rpy="0 0 0" xyz="0 0 0"/>
      <geometry>
        <box size="0.022 0.00635 0.0375"/>
      </geometry>
      <material name="">
        <color rgba="0.9 0.0 0.0 1"/>
      </material>
    </collision>
  </link>
  <link name="right_inner_knuckle">
    <inertial>
      <origin rpy="0 0 0" xyz="0.000123011831763771 0.0507850843201817 0.00103968640075166"/>
      <mass value="0.0271177346495152"/>
      <inertia ixx="2.61910379223783E-05" ixy="-2.43616858946494E-07" ixz="-6.37789906117123E-09" iyy="2.8270243746167E-06" iyz="-5.37200748039765E-07" izz="2.83695868220296E-05"/>
    </inertial>
    <visual>
      <origin rpy="0 0 0" xyz="0 0 0"/>
      <geometry>
        <mesh filename="file:///home/yuandi/tidybot_platform/install/tidybot_description/share/tidybot_description/meshes/grippers/robotiq_2f_85/visual/robotiq_arg2f_85_inner_knuckle.dae" scale="0.001 0.001 0.001"/>
      </geometry>
      <material name="">
        <color rgba="0.1 0.1 0.1 1"/>
      </material>
    </visual>
    <collision>
      <origin rpy="0 0 0" xyz="0 0 0"/>
      <geometry>
        <mesh filename="file:///home/yuandi/tidybot_platform/install/tidybot_description/share/tidybot_description/meshes/grippers/robotiq_2f_85/collision/robotiq_arg2f_85_inner_knuckle.dae" scale="0.001 0.001 0.001"/>
      </geometry>
    </collision>
  </link>
  <joint name="left_outer_knuckle_joint" type="revolute">
    <origin rpy="0 0 3.141592653589793" xyz="0 -0.0306011 0.054904"/>
    <parent link="robotiq_arg2f_base_link"/>
    <child link="left_outer_knuckle"/>
    <axis xyz="1 0 0"/>
    <limit effort="1000" lower="-0.01" upper="0.8" velocity="2.0"/>
  </joint>
  <joint name="left_outer_finger_joint" type="fixed">
    <origin rpy="0 0 0" xyz="0 0.0315 -0.0041"/>
    <parent link="left_outer_knuckle"/>
    <child link="left_outer_finger"/>
    <axis xyz="1 0 0"/>
  </joint>
  <joint name="left_inner_knuckle_joint" type="revolute">
    <!-- <origin xyz="0 ${reflect * -0.0127} 0.06142" rpy="${pi / 2 + .725} 0 ${(reflect - 1) * pi / 2}" /> -->
    <origin rpy="0 0 3.141592653589793" xyz="0 -0.0127 0.06142"/>
    <parent link="robotiq_arg2f_base_link"/>
    <child link="left_inner_knuckle"/>
    <axis xyz="1 0 0"/>
    <limit effort="1000" lower="-0.01" upper="0.8757" velocity="2.0"/>
    <!-- <mimic joint="${prefix}finger_joint" multiplier="1" offset="0" /> -->
  </joint>
  <joint name="left_inner_finger_joint" type="revolute">
    <origin rpy="0 0 0" xyz="0 0.0061 0.0471"/>
    <parent link="left_outer_finger"/>
    <child link="left_inner_finger"/>
    <axis xyz="1 0 0"/>
    <limit effort="1000" lower="-0.8757" upper="0.8757" velocity="2.0"/>
    <!-- <mimic joint="${prefix}finger_joint" multiplier="-1" offset="0" /> -->
  </joint>
  <joint name="left_inner_finger_pad_joint" type="fixed">
    <origin rpy="0 0 0" xyz="0 -0.0220203446692936 0.03242"/>
    <parent link="left_inner_finger"/>
    <child link="left_inner_finger_pad"/>
    <axis xyz="0 0 1"/>
  </joint>
  <joint name="right_outer_knuckle_joint" type="revolute">
    <origin rpy="0 0 0" xyz="0 0.0306011 0.054904"/>
    <parent link="robotiq_arg2f_base_link"/>
    <child link="right_outer_knuckle"/>
    <axis xyz="1 0 0"/>
    <limit effort="1000" lower="-0.01" upper="0.81" velocity="2.0"/>
    <!-- <mimic joint="${prefix}finger_joint" multiplier="1" offset="0" /> -->
  </joint>
  <joint name="right_outer_finger_joint" type="fixed">
    <origin rpy="0 0 0" xyz="0 0.0315 -0.0041"/>
    <parent link="right_outer_knuckle"/>
    <child link="right_outer_finger"/>
    <axis xyz="1 0 0"/>
  </joint>
  <joint name="right_inner_knuckle_joint" type="revolute">
    <!-- <origin xyz="0 ${reflect * -0.0127} 0.06142" rpy="${pi / 2 + .725} 0 ${(reflect - 1) * pi / 2}" /> -->
    <origin rpy="0 0 0.0" xyz="0 0.0127 0.06142"/>
    <parent link="robotiq_arg2f_base_link"/>
    <child link="right_inner_knuckle"/>
    <axis xyz="1 0 0"/>
    <limit effort="1000" lower="-0.01" upper="0.8757" velocity="2.0"/>
    <!-- <mimic joint="${prefix}finger_joint" multiplier="1" offset="0" /> -->
  </joint>
  <joint name="right_inner_finger_joint" type="revolute">
    <origin rpy="0 0 0" xyz="0 0.0061 0.0471"/>
    <parent link="right_outer_finger"/>
    <child link="right_inner_finger"/>
    <axis xyz="1 0 0"/>
    <limit effort="1000" lower="-0.8757" upper="0.8757" velocity="2.0"/>
    <!-- <mimic joint="${prefix}finger_joint" multiplier="-1" offset="0" /> -->
  </joint>
  <joint name="right_inner_finger_pad_joint" type="fixed">
    <origin rpy="0 0 0" xyz="0 -0.0220203446692936 0.03242"/>
    <parent link="right_inner_finger"/>
    <child link="right_inner_finger_pad"/>
    <axis xyz="0 0 1"/>
  </joint>
  <!-- Transmissions are loaded in the generic kortex xacro when simulation is enabled -->
  <!-- <xacro:robotiq_arg2f_transmission prefix="${prefix}"/> -->
  <ros2_control name="TidybotSystem" type="system">
    <hardware>
      <plugin>gz_ros2_control/GazeboSimSystem</plugin>
    </hardware>
    <joint name="joint_x">
      <command_interface name="velocity"/>
      <state_interface name="position"/>
      <state_interface name="velocity"/>
      <param name="position_proportional_gain">0.1</param>
    </joint>
    <joint name="joint_x">
      <command_interface name="position"/>
      <state_interface name="position"/>
      <state_interface name="velocity"/>
      <param name="position_proportional_gain">0.1</param>
    </joint>
    <joint name="joint_y">
      <command_interface name="velocity"/>
      <state_interface name="position"/>
      <state_interface name="velocity"/>
      <param name="position_proportional_gain">0.1</param>
    </joint>
    <joint name="joint_y">
      <command_interface name="position"/>
      <state_interface name="position"/>
      <state_interface name="velocity"/>
      <param name="position_proportional_gain">0.1</param>
    </joint>
    <joint name="joint_th">
      <command_interface name="velocity"/>
      <state_interface name="position"/>
      <state_interface name="velocity"/>
      <param name="position_proportional_gain">0.1</param>
    </joint>
    <joint name="joint_th">
      <command_interface name="position"/>
      <state_interface name="position"/>
      <state_interface name="velocity"/>
      <param name="position_proportional_gain">0.1</param>
    </joint>
    <joint name="joint_1">
      <command_interface name="position"/>
      <state_interface name="position"/>
      <state_interface name="velocity"/>
      <param name="position_proportional_gain">0.1</param>
    </joint>
    <joint name="joint_2">
      <command_interface name="position"/>
      <state_interface name="position"/>
      <state_interface name="velocity"/>
      <param name="position_proportional_gain">0.1</param>
    </joint>
    <joint name="joint_3">
      <command_interface name="position"/>
      <state_interface name="position"/>
      <state_interface name="velocity"/>
      <param name="position_proportional_gain">0.1</param>
    </joint>
    <joint name="joint_4">
      <command_interface name="position"/>
      <state_interface name="position"/>
      <state_interface name="velocity"/>
      <param name="position_proportional_gain">0.1</param>
    </joint>
    <joint name="joint_5">
      <command_interface name="position"/>
      <state_interface name="position"/>
      <state_interface name="velocity"/>
      <param name="position_proportional_gain">0.1</param>
    </joint>
    <joint name="joint_6">
      <command_interface name="position"/>
      <state_interface name="position"/>
      <state_interface name="velocity"/>
      <param name="position_proportional_gain">0.1</param>
    </joint>
    <joint name="joint_7">
      <command_interface name="position"/>
      <state_interface name="position"/>
      <state_interface name="velocity"/>
      <param name="position_proportional_gain">0.1</param>
    </joint>
    <joint name="right_inner_finger_joint">
      <command_interface name="position"/>
      <state_interface name="position"/>
      <state_interface name="velocity"/>
      <param name="position_proportional_gain">0.1</param>
    </joint>
    <joint name="right_outer_knuckle_joint">
      <command_interface name="position"/>
      <state_interface name="position"/>
      <state_interface name="velocity"/>
      <param name="position_proportional_gain">0.1</param>
    </joint>
    <joint name="right_inner_knuckle_joint">
      <command_interface name="position"/>
      <state_interface name="position"/>
      <state_interface name="velocity"/>
      <param name="position_proportional_gain">0.1</param>
    </joint>
    <joint name="left_inner_finger_joint">
      <command_interface name="position"/>
      <state_interface name="position"/>
      <state_interface name="velocity"/>
      <param name="position_proportional_gain">0.1</param>
    </joint>
    <joint name="left_outer_knuckle_joint">
      <command_interface name="position"/>
      <state_interface name="position"/>
      <state_interface name="velocity"/>
      <param name="position_proportional_gain">0.1</param>
    </joint>
    <joint name="left_inner_knuckle_joint">
      <command_interface name="position"/>
      <state_interface name="position"/>
      <state_interface name="velocity"/>
      <param name="position_proportional_gain">0.1</param>
    </joint>
  </ros2_control>
  <gazebo>
    <plugin filename="gz_ros2_control-system" name="gz_ros2_control::GazeboSimROS2ControlPlugin">
      <parameters>/home/yuandi/tidybot_platform/install/tidybot_description/share/tidybot_description/config/tidybot_controllers.yaml</parameters>
      <robot_description_param>robot_description</robot_description_param>
    </plugin>
    <plugin filename="libignition-gazebo-sensors-system.so" name="ignition::gazebo::systems::Sensors"/>
    <!-- <self_collide>true</self_collide> -->
  </gazebo>
  <!-- <gazebo>
    <plugin filename="ignition-gazebo-joint-state-publisher-system" name="ignition::gazebo::systems::JointStatePublisher"/>

    <plugin
        filename="ignition-gazebo-pose-publisher-system"
        name="ignition::gazebo::systems::PosePublisher">
        <publish_link_pose>true</publish_link_pose>

        <use_pose_vector_msg>true</use_pose_vector_msg>
    </plugin>

  </gazebo> -->
  <gazebo reference="camera_link">
    <sensor name="camera" type="rgbd_camera">
      <always_on>1</always_on>
      <update_rate>30</update_rate>
      <visualize>true</visualize>
      <pose>0 -0.01 0.01 0 4.7124 1.5708</pose>
      <topic>/camera</topic>
      <gz_frame_id>camera_link</gz_frame_id>
      <camera>
        <horizontal_fov>1.047</horizontal_fov>
        <image>
          <width>640</width>
          <height>480</height>
          <format>R8G8B8</format>
        </image>
        <clip>
          <near>0.01</near>
          <far>3.0</far>
        </clip>
        <noise>
          <type>gaussian</type>
          <mean>0.0</mean>
          <stddev>0.007</stddev>
        </noise>
      </camera>
    </sensor>
  </gazebo>
  <gazebo reference="base">
    <sensor name="third_person_camera" type="rgbd_camera">
      <always_on>1</always_on>
      <update_rate>30</update_rate>
      <visualize>true</visualize>
      <pose>0 2 0.5 0 4.7124 1.5708</pose>
      <topic>/third_person_camera</topic>
      <frame_name>base</frame_name>
      <camera>
        <horizontal_fov>1.047</horizontal_fov>
        <image>
          <width>640</width>
          <height>480</height>
          <format>R8G8B8</format>
        </image>
        <clip>
          <near>0.01</near>
          <far>3.0</far>
        </clip>
        <noise>
          <type>gaussian</type>
          <mean>0.0</mean>
          <stddev>0.007</stddev>
        </noise>
      </camera>
    </sensor>
  </gazebo>
  <transmission name="joint_1_trans">
    <type>transmission_interface/SimpleTransmission</type>
    <actuator name="joint_1_motor"/>
    <joint name="joint_1"/>
    <mechanicalReduction>1</mechanicalReduction>
  </transmission>
  <transmission name="joint_2_trans">
    <type>transmission_interface/SimpleTransmission</type>
    <actuator name="joint_2_motor"/>
    <joint name="joint_2"/>
    <mechanicalReduction>1</mechanicalReduction>
  </transmission>
  <transmission name="joint_3_trans">
    <type>transmission_interface/SimpleTransmission</type>
    <actuator name="joint_3_motor"/>
    <joint name="joint_3"/>
    <mechanicalReduction>1</mechanicalReduction>
  </transmission>
  <transmission name="joint_4_trans">
    <type>transmission_interface/SimpleTransmission</type>
    <actuator name="joint_4_motor"/>
    <joint name="joint_4"/>
    <mechanicalReduction>1</mechanicalReduction>
  </transmission>
  <transmission name="joint_5_trans">
    <type>transmission_interface/SimpleTransmission</type>
    <actuator name="joint_5_motor"/>
    <joint name="joint_5"/>
    <mechanicalReduction>1</mechanicalReduction>
  </transmission>
  <transmission name="joint_6_trans">
    <type>transmission_interface/SimpleTransmission</type>
    <actuator name="joint_6_motor"/>
    <joint name="joint_6"/>
    <mechanicalReduction>1</mechanicalReduction>
  </transmission>
  <transmission name="joint_7_trans">
    <type>transmission_interface/SimpleTransmission</type>
    <actuator name="joint_7_motor"/>
    <joint name="joint_7"/>
    <mechanicalReduction>1</mechanicalReduction>
  </transmission>
  <transmission name="joint_x_trans">
    <type>transmission_interface/SimpleTransmission</type>
    <joint name="joint_x"/>
    <actuator name="joint_x_motor">
      <mechanicalReduction>1</mechanicalReduction>
    </actuator>
  </transmission>
  <transmission name="joint_y_trans">
    <type>transmission_interface/SimpleTransmission</type>
    <joint name="joint_y"/>
    <actuator name="joint_y_motor">
      <mechanicalReduction>1</mechanicalReduction>
    </actuator>
  </transmission>
  <transmission name="joint_th_trans">
    <type>transmission_interface/SimpleTransmission</type>
    <joint name="joint_th"/>
    <actuator name="joint_th_motor">
      <mechanicalReduction>1</mechanicalReduction>
    </actuator>
  </transmission>
  <transmission name="left_inner_knuckle_joint_trans">
    <type>transmission_interface/SimpleTransmission</type>
    <joint name="left_inner_knuckle_joint"/>
    <actuator name="left_inner_knuckle_joint_motor"/>
    <mechanicalReduction>1</mechanicalReduction>
  </transmission>
  <transmission name="right_inner_knuckle_joint_trans">
    <type>transmission_interface/SimpleTransmission</type>
    <joint name="right_inner_knuckle_joint"/>
    <actuator name="right_inner_knuckle_joint_motor"/>
    <mechanicalReduction>1</mechanicalReduction>
  </transmission>
  <transmission name="left_inner_finger_joint_trans">
    <type>transmission_interface/SimpleTransmission</type>
    <joint name="left_inner_finger_joint"/>
    <actuator name="left_inner_finger_joint_motor"/>
    <mechanicalReduction>1</mechanicalReduction>
  </transmission>
  <transmission name="right_inner_finger_joint_trans">
    <type>transmission_interface/SimpleTransmission</type>
    <joint name="right_inner_finger_joint"/>
    <actuator name="right_inner_finger_joint_motor"/>
    <mechanicalReduction>1</mechanicalReduction>
  </transmission>
  <transmission name="left_outer_knuckle_joint_trans">
    <type>transmission_interface/SimpleTransmission</type>
    <joint name="left_outer_knuckle_joint"/>
    <actuator name="left_outer_knuckle_joint_motor"/>
    <mechanicalReduction>1</mechanicalReduction>
  </transmission>
  <transmission name="right_outer_knuckle_joint_trans">
    <type>transmission_interface/SimpleTransmission</type>
    <joint name="right_outer_knuckle_joint"/>
    <actuator name="right_outer_knuckle_joint_motor"/>
    <mechanicalReduction>1</mechanicalReduction>
  </transmission>
</robot>
