<?xml version="1.0" ?>
<!-- =================================================================================== -->
<!-- |    This document was autogenerated by xacro from tidybot.xacro                  | -->
<!-- |    EDITING THIS FILE BY HAND IS NOT RECOMMENDED                                 | -->
<!-- =================================================================================== -->
<robot name="tidybot">
  <!-- <xacro:load_base prefix=""/> -->
  <link name="world">
    <origin rpy="0.0 0.0 0.0" xyz="0.0 0.0 0.0"/>
  </link>
  <link name="base_link">
    <inertial>
      <origin rpy="0.0 0.0 0.0" xyz="0.0 0.0 0.035"/>
      <mass value="60.0"/>
      <inertia ixx="0.001" ixy="0" ixz="0" iyy="0.001" iyz="0" izz="0.001"/>
    </inertial>
    <visual name="bumper">
      <origin rpy="-2.442021632452952 -1.5707963267948966 0.0" xyz="-1.3915598211675165e-07 -2.058962502098711e-07 0.05386474576457055"/>
      <geometry>
        <mesh filename="file:///home/janchen/Documents/ros2/tidybot_ws/install/tidybot_description/share/tidybot_description/meshes/base/bumper.stl"/>
      </geometry>
      <material name="white"/>
    </visual>
    <collision name="bumper">
      <origin rpy="-2.442021632452952 -1.5707963267948966 0.0" xyz="-1.3915598211675165e-07 -2.058962502098711e-07 0.05386474576457055"/>
      <geometry>
        <mesh filename="file:///home/janchen/Documents/ros2/tidybot_ws/install/tidybot_description/share/tidybot_description/meshes/base/bumper.stl"/>
      </geometry>
    </collision>
    <visual name="bottom_plate">
      <origin rpy="1.6659662035857206 -1.5707963267948966 0.0" xyz="4.155854111430312e-11 1.8201972332496634e-11 0.08495000004768373"/>
      <geometry>
        <mesh filename="file:///home/janchen/Documents/ros2/tidybot_ws/install/tidybot_description/share/tidybot_description/meshes/base/bottom_plate.stl"/>
      </geometry>
      <material name="white"/>
    </visual>
    <collision name="bottom_plate">
      <origin rpy="1.6659662035857206 -1.5707963267948966 0.0" xyz="4.155854111430312e-11 1.8201972332496634e-11 0.08495000004768373"/>
      <geometry>
        <mesh filename="file:///home/janchen/Documents/ros2/tidybot_ws/install/tidybot_description/share/tidybot_description/meshes/base/bottom_plate.stl"/>
      </geometry>
    </collision>
    <visual name="body">
      <origin rpy="-1.5707963267948966 -1.570779305272103 3.141592653589793" xyz="7.590768644441668e-06 -6.000635064190085e-10 0.20330222068596052"/>
      <geometry>
        <mesh filename="file:///home/janchen/Documents/ros2/tidybot_ws/install/tidybot_description/share/tidybot_description/meshes/base/body.stl"/>
      </geometry>
      <material name="white"/>
    </visual>
    <collision name="body">
      <origin rpy="-1.5707963267948966 -1.570779305272103 3.141592653589793" xyz="7.590768644441668e-06 -6.000635064190085e-10 0.20330222068596052"/>
      <geometry>
        <mesh filename="file:///home/janchen/Documents/ros2/tidybot_ws/install/tidybot_description/share/tidybot_description/meshes/base/body.stl"/>
      </geometry>
    </collision>
    <visual name="top_plate">
      <origin rpy="1.6906681075416252 -1.5707963267948966 0.0" xyz="-2.9658670629084936e-11 -3.476524862019053e-11 0.3216499984264373"/>
      <geometry>
        <mesh filename="file:///home/janchen/Documents/ros2/tidybot_ws/install/tidybot_description/share/tidybot_description/meshes/base/top_plate.stl"/>
      </geometry>
      <material name="white"/>
    </visual>
    <collision name="top_plate">
      <origin rpy="1.6906681075416252 -1.5707963267948966 0.0" xyz="-2.9658670629084936e-11 -3.476524862019053e-11 0.3216499984264373"/>
      <geometry>
        <mesh filename="file:///home/janchen/Documents/ros2/tidybot_ws/install/tidybot_description/share/tidybot_description/meshes/base/top_plate.stl"/>
      </geometry>
    </collision>
    <visual name="arm_plate">
      <origin rpy="1.5707963267948966 -1.5707963267948966 0.0" xyz="-2.7580994002430455e-12 -3.3382504263355704e-12 0.32999999883475684"/>
      <geometry>
        <mesh filename="file:///home/janchen/Documents/ros2/tidybot_ws/install/tidybot_description/share/tidybot_description/meshes/base/arm_plate.stl"/>
      </geometry>
      <material name="white"/>
    </visual>
    <collision name="arm_plate">
      <origin rpy="1.5707963267948966 -1.5707963267948966 0.0" xyz="-2.7580994002430455e-12 -3.3382504263355704e-12 0.32999999883475684"/>
      <geometry>
        <mesh filename="file:///home/janchen/Documents/ros2/tidybot_ws/install/tidybot_description/share/tidybot_description/meshes/base/arm_plate.stl"/>
      </geometry>
    </collision>
    <visual name="bumper">
      <origin rpy="-2.442021632452952 -1.5707963267948966 0.0" xyz="-1.3915598211675165e-07 -2.058962502098711e-07 0.05386474576457055"/>
      <geometry>
        <mesh filename="file:///home/janchen/Documents/ros2/tidybot_ws/install/tidybot_description/share/tidybot_description/meshes/base/bumper.stl"/>
      </geometry>
      <material name="white"/>
    </visual>
    <collision name="bumper">
      <origin rpy="-2.442021632452952 -1.5707963267948966 0.0" xyz="-1.3915598211675165e-07 -2.058962502098711e-07 0.05386474576457055"/>
      <geometry>
        <mesh filename="file:///home/janchen/Documents/ros2/tidybot_ws/install/tidybot_description/share/tidybot_description/meshes/base/bumper.stl"/>
      </geometry>
    </collision>
    <visual name="bottom_plate">
      <origin rpy="1.6659662035857206 -1.5707963267948966 0.0" xyz="4.155854111430312e-11 1.8201972332496634e-11 0.08495000004768373"/>
      <geometry>
        <mesh filename="file:///home/janchen/Documents/ros2/tidybot_ws/install/tidybot_description/share/tidybot_description/meshes/base/bottom_plate.stl"/>
      </geometry>
      <material name="white"/>
    </visual>
    <collision name="bottom_plate">
      <origin rpy="1.6659662035857206 -1.5707963267948966 0.0" xyz="4.155854111430312e-11 1.8201972332496634e-11 0.08495000004768373"/>
      <geometry>
        <mesh filename="file:///home/janchen/Documents/ros2/tidybot_ws/install/tidybot_description/share/tidybot_description/meshes/base/bottom_plate.stl"/>
      </geometry>
    </collision>
    <visual name="body">
      <origin rpy="-1.5707963267948966 -1.570779305272103 3.141592653589793" xyz="7.590768644441668e-06 -6.000635064190085e-10 0.20330222068596052"/>
      <geometry>
        <mesh filename="file:///home/janchen/Documents/ros2/tidybot_ws/install/tidybot_description/share/tidybot_description/meshes/base/body.stl"/>
      </geometry>
      <material name="white"/>
    </visual>
    <collision name="body">
      <origin rpy="-1.5707963267948966 -1.570779305272103 3.141592653589793" xyz="7.590768644441668e-06 -6.000635064190085e-10 0.20330222068596052"/>
      <geometry>
        <mesh filename="file:///home/janchen/Documents/ros2/tidybot_ws/install/tidybot_description/share/tidybot_description/meshes/base/body.stl"/>
      </geometry>
    </collision>
    <visual name="top_plate">
      <origin rpy="1.6906681075416252 -1.5707963267948966 0.0" xyz="-2.9658670629084936e-11 -3.476524862019053e-11 0.3216499984264373"/>
      <geometry>
        <mesh filename="file:///home/janchen/Documents/ros2/tidybot_ws/install/tidybot_description/share/tidybot_description/meshes/base/top_plate.stl"/>
      </geometry>
      <material name="white"/>
    </visual>
    <collision name="top_plate">
      <origin rpy="1.6906681075416252 -1.5707963267948966 0.0" xyz="-2.9658670629084936e-11 -3.476524862019053e-11 0.3216499984264373"/>
      <geometry>
        <mesh filename="file:///home/janchen/Documents/ros2/tidybot_ws/install/tidybot_description/share/tidybot_description/meshes/base/top_plate.stl"/>
      </geometry>
    </collision>
    <visual name="arm_plate">
      <origin rpy="1.5707963267948966 -1.5707963267948966 0.0" xyz="-2.7580994002430455e-12 -3.3382504263355704e-12 0.32999999883475684"/>
      <geometry>
        <mesh filename="file:///home/janchen/Documents/ros2/tidybot_ws/install/tidybot_description/share/tidybot_description/meshes/base/arm_plate.stl"/>
      </geometry>
      <material name="white"/>
    </visual>
    <collision name="arm_plate">
      <origin rpy="1.5707963267948966 -1.5707963267948966 0.0" xyz="-2.7580994002430455e-12 -3.3382504263355704e-12 0.32999999883475684"/>
      <geometry>
        <mesh filename="file:///home/janchen/Documents/ros2/tidybot_ws/install/tidybot_description/share/tidybot_description/meshes/base/arm_plate.stl"/>
      </geometry>
    </collision>
  </link>
  <link name="joint_x_jointbody">
    <inertial>
      <origin rpy="0.0 0.0 0.0" xyz="0.0 0.0 0.0"/>
      <mass value="0.001"/>
      <inertia ixx="1e-09" ixy="0" ixz="0" iyy="1e-09" iyz="0" izz="1e-09"/>
    </inertial>
  </link>
  <joint name="joint_x" type="prismatic">
    <origin rpy="0.0 0.0 0.0" xyz="0.0 0.0 0.0"/>
    <parent link="world"/>
    <child link="joint_x_jointbody"/>
    <axis xyz="1 0 0"/>
    <limit effort="100" lower="-10.0" upper="10.0" velocity="1"/>
    <dynamics damping="1.0" friction="1.0"/>
  </joint>
  <transmission name="joint_x_trans">
    <type>transmission_interface/SimpleTransmission</type>
    <joint name="joint_x"/>
    <actuator name="joint_x_motor">
      <mechanicalReduction>1</mechanicalReduction>
    </actuator>
  </transmission>
  <link name="joint_y_jointbody">
    <inertial>
      <origin rpy="0.0 0.0 0.0" xyz="0.0 0.0 0.0"/>
      <mass value="0.001"/>
      <inertia ixx="1e-09" ixy="0" ixz="0" iyy="1e-09" iyz="0" izz="1e-09"/>
    </inertial>
  </link>
  <joint name="joint_y" type="prismatic">
    <origin rpy="0.0 0.0 0.0" xyz="0.0 0.0 0.0"/>
    <parent link="joint_x_jointbody"/>
    <child link="joint_y_jointbody"/>
    <axis xyz="0 1 0"/>
    <limit effort="100" lower="-10.0" upper="10.0" velocity="1"/>
    <dynamics damping="1.0" friction="1.0"/>
  </joint>
  <transmission name="joint_y_trans">
    <type>transmission_interface/SimpleTransmission</type>
    <joint name="joint_y"/>
    <actuator name="joint_y_motor">
      <mechanicalReduction>1</mechanicalReduction>
    </actuator>
  </transmission>
  <link name="joint_th_jointbody">
    <inertial>
      <origin rpy="0.0 0.0 0.0" xyz="0.0 0.0 0.0"/>
      <mass value="0.001"/>
      <inertia ixx="1e-09" ixy="0" ixz="0" iyy="1e-09" iyz="0" izz="1e-09"/>
    </inertial>
  </link>
  <joint name="joint_th" type="revolute">
    <origin rpy="0.0 0.0 0.0" xyz="0.0 0.0 0.0"/>
    <parent link="joint_y_jointbody"/>
    <child link="joint_th_jointbody"/>
    <axis xyz="0.0 0.0 1.0"/>
    <limit effort="100" lower="-3.14" upper="3.14" velocity="1"/>
    <dynamics damping="1.0" friction="1.0"/>
  </joint>
  <transmission name="joint_th_trans">
    <type>transmission_interface/SimpleTransmission</type>
    <joint name="joint_th"/>
    <actuator name="joint_th_motor">
      <mechanicalReduction>1</mechanicalReduction>
    </actuator>
  </transmission>
  <joint name="joint_th_offset" type="fixed">
    <origin rpy="0.0 0.0 0.0" xyz="-0.0 -0.0 -0.0"/>
    <parent link="joint_th_jointbody"/>
    <child link="base_link"/>
    <axis xyz="0.0 0.0 1.0"/>
    <limit effort="100" lower="0.0" upper="0.0" velocity="100"/>
  </joint>
  <material name="white">
    <color rgba="1 1 1 1"/>
  </material>
  <joint name="arm_base_joint" type="fixed">
    <origin rpy="0 0 0" xyz="0 0 0.335"/>
    <parent link="base_link"/>
    <child link="arm_base_link"/>
  </joint>
  <link name="arm_base_link">
    <inertial>
      <origin rpy="0 0 0" xyz="0.00244324 0.00015573 0.08616742"/>
      <mass value="1.14608471"/>
      <inertia ixx="0.00335854" ixy="3.9E-07" ixz="0.00010989" iyy="0.003311" iyz="1.91E-06" izz="0.00077158"/>
    </inertial>
    <visual>
      <origin rpy="0 0 0" xyz="0 0 0"/>
      <geometry>
        <mesh filename="file:///home/janchen/Documents/ros2/tidybot_ws/install/tidybot_description/share/tidybot_description/meshes/arms/gen3_lite/base_link.STL"/>
      </geometry>
      <material name="">
        <color rgba="0.803 0.824 0.820 1"/>
      </material>
    </visual>
    <collision>
      <origin rpy="0 0 0" xyz="0 0 0"/>
      <geometry>
        <mesh filename="file:///home/janchen/Documents/ros2/tidybot_ws/install/tidybot_description/share/tidybot_description/meshes/arms/gen3_lite/base_link.STL"/>
      </geometry>
    </collision>
  </link>
  <gazebo reference="arm_base_link">
    <material>Gazebo/Gray</material>
  </gazebo>
  <link name="shoulder_link">
    <inertial>
      <origin rpy="0 0 0" xyz="2.477E-05 0.02213531 0.09937686"/>
      <mass value="0.95974404"/>
      <inertia ixx="0.00165947" ixy="2E-08" ixz="3.6E-07" iyy="0.00140355" iyz="0.00034927" izz="0.00089493"/>
    </inertial>
    <visual>
      <origin rpy="0 0 0" xyz="0 0 0"/>
      <geometry>
        <mesh filename="file:///home/janchen/Documents/ros2/tidybot_ws/install/tidybot_description/share/tidybot_description/meshes/arms/gen3_lite/shoulder_link.STL"/>
      </geometry>
      <material name="">
        <color rgba="0.803 0.824 0.820 1"/>
      </material>
    </visual>
    <collision>
      <origin rpy="0 0 0" xyz="0 0 0"/>
      <geometry>
        <mesh filename="file:///home/janchen/Documents/ros2/tidybot_ws/install/tidybot_description/share/tidybot_description/meshes/arms/gen3_lite/shoulder_link.STL"/>
      </geometry>
    </collision>
  </link>
  <gazebo reference="shoulder_link">
    <material>Gazebo/Gray</material>
  </gazebo>
  <joint name="joint_1" type="revolute">
    <origin rpy="0 0 0" xyz="0 0 0.12825"/>
    <parent link="arm_base_link"/>
    <child link="shoulder_link"/>
    <axis xyz="0 0 1"/>
    <limit effort="10" lower="-2.69" upper="2.69" velocity="1.6"/>
    <dynamics damping="1.0" friction="1.0"/>
  </joint>
  <transmission name="joint1_trans">
    <type>transmission_interface/SimpleTransmission</type>
    <joint name="joint_1"/>
    <actuator name="joint1_motor">
      <mechanicalReduction>1</mechanicalReduction>
    </actuator>
  </transmission>
  <link name="arm_link">
    <inertial>
      <origin rpy="0 0 0" xyz="0.02998299 0.21154808 0.0453031"/>
      <mass value="1.17756164"/>
      <inertia ixx="0.01149277" ixy="1E-06" ixz="1.6E-07" iyy="0.00102851" iyz="0.00140765" izz="0.01133492"/>
    </inertial>
    <visual>
      <origin rpy="0 0 0" xyz="0 0 0"/>
      <geometry>
        <mesh filename="file:///home/janchen/Documents/ros2/tidybot_ws/install/tidybot_description/share/tidybot_description/meshes/arms/gen3_lite/arm_link.STL"/>
      </geometry>
      <material name="">
        <color rgba="0.803 0.824 0.820 1"/>
      </material>
    </visual>
    <collision>
      <origin rpy="0 0 0" xyz="0 0 0"/>
      <geometry>
        <mesh filename="file:///home/janchen/Documents/ros2/tidybot_ws/install/tidybot_description/share/tidybot_description/meshes/arms/gen3_lite/arm_link.STL"/>
      </geometry>
    </collision>
  </link>
  <gazebo reference="arm_link">
    <material>Gazebo/Gray</material>
  </gazebo>
  <joint name="joint_2" type="revolute">
    <origin rpy="1.5708 0 0" xyz="0 -0.03 0.115"/>
    <parent link="shoulder_link"/>
    <child link="arm_link"/>
    <axis xyz="0 0 1"/>
    <limit effort="14" lower="-2.69" upper="2.69" velocity="1.6"/>
    <dynamics damping="1.0" friction="1.0"/>
  </joint>
  <transmission name="joint2_trans">
    <type>transmission_interface/SimpleTransmission</type>
    <joint name="joint_2"/>
    <actuator name="joint2_motor">
      <mechanicalReduction>1</mechanicalReduction>
    </actuator>
  </transmission>
  <link name="forearm_link">
    <inertial>
      <origin rpy="0 0 0" xyz="0.0301559 0.09502206 0.0073555"/>
      <mass value="0.59767669"/>
      <inertia ixx="0.00163256" ixy="7.11E-06" ixz="1.54E-06" iyy="0.00029798" iyz="9.587E-05" izz="0.00169091"/>
    </inertial>
    <visual>
      <origin rpy="0 0 0" xyz="0 0 0"/>
      <geometry>
        <mesh filename="file:///home/janchen/Documents/ros2/tidybot_ws/install/tidybot_description/share/tidybot_description/meshes/arms/gen3_lite/forearm_link.STL"/>
      </geometry>
      <material name="">
        <color rgba="0.803 0.824 0.820 1"/>
      </material>
    </visual>
    <collision>
      <origin rpy="0 0 0" xyz="0 0 0"/>
      <geometry>
        <mesh filename="file:///home/janchen/Documents/ros2/tidybot_ws/install/tidybot_description/share/tidybot_description/meshes/arms/gen3_lite/forearm_link.STL"/>
      </geometry>
    </collision>
  </link>
  <gazebo reference="forearm_link">
    <material>Gazebo/Gray</material>
  </gazebo>
  <joint name="joint_3" type="revolute">
    <origin rpy="-3.1416 0 0" xyz="0 0.28 0"/>
    <parent link="arm_link"/>
    <child link="forearm_link"/>
    <axis xyz="0 0 1"/>
    <limit effort="10" lower="-2.69" upper="2.69" velocity="1.6"/>
    <dynamics damping="1.0" friction="1.0"/>
  </joint>
  <transmission name="joint3_trans">
    <type>transmission_interface/SimpleTransmission</type>
    <joint name="joint_3"/>
    <actuator name="joint3_motor">
      <mechanicalReduction>1</mechanicalReduction>
    </actuator>
  </transmission>
  <link name="lower_wrist_link">
    <inertial>
      <origin rpy="0 0 0" xyz="0.00575149 0.01000443 0.08719207"/>
      <mass value="0.52693412"/>
      <inertia ixx="0.00069098" ixy="2.4E-07" ixz="0.00016483" iyy="0.00078519" iyz="7.4E-07" izz="0.00034115"/>
    </inertial>
    <visual>
      <origin rpy="0 0 0" xyz="0 0 0"/>
      <geometry>
        <mesh filename="file:///home/janchen/Documents/ros2/tidybot_ws/install/tidybot_description/share/tidybot_description/meshes/arms/gen3_lite/lower_wrist_link.STL"/>
      </geometry>
      <material name="">
        <color rgba="0.803 0.824 0.820 1"/>
      </material>
    </visual>
    <collision>
      <origin rpy="0 0 0" xyz="0 0 0"/>
      <geometry>
        <mesh filename="file:///home/janchen/Documents/ros2/tidybot_ws/install/tidybot_description/share/tidybot_description/meshes/arms/gen3_lite/lower_wrist_link.STL"/>
      </geometry>
    </collision>
  </link>
  <gazebo reference="lower_wrist_link">
    <material>Gazebo/Gray</material>
  </gazebo>
  <joint name="joint_4" type="revolute">
    <origin rpy="1.5708 0 0" xyz="0 -0.14 0.02"/>
    <parent link="forearm_link"/>
    <child link="lower_wrist_link"/>
    <axis xyz="0 0 1"/>
    <limit effort="7" lower="-2.59" upper="2.59" velocity="1.6"/>
    <dynamics damping="1.0" friction="1.0"/>
  </joint>
  <transmission name="joint4_trans">
    <type>transmission_interface/SimpleTransmission</type>
    <joint name="joint_4"/>
    <actuator name="joint4_motor">
      <mechanicalReduction>1</mechanicalReduction>
    </actuator>
  </transmission>
  <link name="upper_wrist_link">
    <inertial>
      <origin rpy="0 0 0" xyz="0.08056517 0.00980409 0.01872799"/>
      <mass value="0.58097325"/>
      <inertia ixx="0.00021268" ixy="5.21E-06" ixz="2.91E-06" iyy="0.00106371" iyz="1.1E-07" izz="0.00108465"/>
    </inertial>
    <visual>
      <origin rpy="0 0 0" xyz="0 0 0"/>
      <geometry>
        <mesh filename="file:///home/janchen/Documents/ros2/tidybot_ws/install/tidybot_description/share/tidybot_description/meshes/arms/gen3_lite/upper_wrist_link.STL"/>
      </geometry>
      <material name="">
        <color rgba="0.803 0.824 0.820 1"/>
      </material>
    </visual>
    <collision>
      <origin rpy="0 0 0" xyz="0 0 0"/>
      <geometry>
        <mesh filename="file:///home/janchen/Documents/ros2/tidybot_ws/install/tidybot_description/share/tidybot_description/meshes/arms/gen3_lite/upper_wrist_link.STL"/>
      </geometry>
    </collision>
  </link>
  <gazebo reference="upper_wrist_link">
    <material>Gazebo/Gray</material>
  </gazebo>
  <joint name="joint_5" type="revolute">
    <origin rpy="0 1.5708 0" xyz="0.0285 0 0.105"/>
    <parent link="lower_wrist_link"/>
    <child link="upper_wrist_link"/>
    <axis xyz="0 0 1"/>
    <limit effort="7" lower="-2.57" upper="2.57" velocity="1.6"/>
    <dynamics damping="1.0" friction="1.0"/>
  </joint>
  <transmission name="joint5_trans">
    <type>transmission_interface/SimpleTransmission</type>
    <joint name="joint_5"/>
    <actuator name="joint5_motor">
      <mechanicalReduction>1</mechanicalReduction>
    </actuator>
  </transmission>
  <link name="end_effector_link"/>
  <joint name="joint_6" type="revolute">
    <origin rpy="0 -1.5708 0" xyz="-0.105 0 0.0285"/>
    <parent link="upper_wrist_link"/>
    <child link="end_effector_link"/>
    <axis xyz="0 0 1"/>
    <limit effort="7" lower="-2.59" upper="2.59" velocity="3.2"/>
    <dynamics damping="1.0" friction="1.0"/>
  </joint>
  <transmission name="joint6_trans">
    <type>transmission_interface/SimpleTransmission</type>
    <joint name="joint_6"/>
    <actuator name="joint6_motor">
      <mechanicalReduction>1</mechanicalReduction>
    </actuator>
  </transmission>
  <!-- Tool frame used by the arm -->
  <link name="tool_frame"/>
  <joint name="tool_frame_joint" type="fixed">
    <origin rpy="0 0 1.57079632679" xyz="0 0 0.130"/>
    <parent link="end_effector_link"/>
    <child link="tool_frame"/>
    <axis xyz="0 0 0"/>
  </joint>
  <!-- Gripper description -->
  <joint name="gripper_base_joint" type="fixed">
    <origin rpy="0 0 0" xyz="0 0 0"/>
    <parent link="end_effector_link"/>
    <child link="gripper_base_link"/>
    <axis xyz="0 0 0"/>
  </joint>
  <link name="gripper_base_link">
    <inertial>
      <origin rpy="0 0 0" xyz="4.03E-06 1.08E-05 0.041397"/>
      <mass value="0.1395"/>
      <inertia ixx="0.00011614" ixy="1E-08" ixz="4E-08" iyy="0.00010327" iyz="0" izz="9.707E-05"/>
    </inertial>
    <visual>
      <origin rpy="0 0 0" xyz="0 0 0"/>
      <geometry>
        <mesh filename="file:///home/janchen/Documents/ros2/tidybot_ws/install/tidybot_description/share/tidybot_description/meshes/grippers/gen3_lite_2f/gripper_base_link.STL"/>
      </geometry>
      <material name="">
        <color rgba="0.803 0.824 0.820 1"/>
      </material>
    </visual>
    <collision>
      <origin rpy="0 0 0" xyz="0 0 0"/>
      <geometry>
        <mesh filename="file:///home/janchen/Documents/ros2/tidybot_ws/install/tidybot_description/share/tidybot_description/meshes/grippers/gen3_lite_2f/gripper_base_link.STL"/>
      </geometry>
    </collision>
  </link>
  <gazebo reference="gripper_base_link">
    <material>Gazebo/Gray</material>
  </gazebo>
  <link name="right_finger_prox_link">
    <inertial>
      <origin rpy="0 0 0" xyz="0.020257 0.0063483 6.991E-05"/>
      <mass value="0.018385"/>
      <inertia ixx="2.29E-06" ixy="1.43E-06" ixz="0" iyy="4.56E-06" iyz="0" izz="4.77E-06"/>
    </inertial>
    <visual>
      <origin rpy="0 0 0" xyz="0 0 0"/>
      <geometry>
        <mesh filename="file:///home/janchen/Documents/ros2/tidybot_ws/install/tidybot_description/share/tidybot_description/meshes/grippers/gen3_lite_2f/right_finger_prox_link.STL"/>
      </geometry>
      <material name="">
        <color rgba="0.803 0.824 0.820 1"/>
      </material>
    </visual>
    <collision>
      <origin rpy="0 0 0" xyz="0 0 0"/>
      <geometry>
        <mesh filename="file:///home/janchen/Documents/ros2/tidybot_ws/install/tidybot_description/share/tidybot_description/meshes/grippers/gen3_lite_2f/right_finger_prox_link.STL"/>
      </geometry>
    </collision>
  </link>
  <gazebo reference="right_finger_prox_link">
    <material>Gazebo/Gray</material>
  </gazebo>
  <joint name="right_finger_bottom_joint" type="revolute">
    <origin rpy="0 1.5708 0" xyz="0 -0.030501 0.070003"/>
    <parent link="gripper_base_link"/>
    <child link="right_finger_prox_link"/>
    <axis xyz="0 0 1"/>
    <limit effort="1000" lower="-0.09" upper="0.96" velocity="0.6"/>
    <dynamics damping="1.0" friction="1.0"/>
  </joint>
  <transmission name="right_finger_bottom_joint_trans">
    <type>transmission_interface/SimpleTransmission</type>
    <joint name="right_finger_bottom_joint"/>
    <actuator name="right_finger_bottom_joint_motor">
      <mechanicalReduction>1</mechanicalReduction>
    </actuator>
  </transmission>
  <link name="right_finger_dist_link">
    <inertial>
      <origin rpy="0 0 0" xyz="0.018488 0.0011091 0"/>
      <mass value="0.010748"/>
      <inertia ixx="6.3E-07" ixy="3.2E-07" ixz="0" iyy="1.83E-06" iyz="0" izz="1.61E-06"/>
    </inertial>
    <visual>
      <origin rpy="0 0 0" xyz="0 0 0"/>
      <geometry>
        <mesh filename="file:///home/janchen/Documents/ros2/tidybot_ws/install/tidybot_description/share/tidybot_description/meshes/grippers/gen3_lite_2f/right_finger_dist_link.STL"/>
      </geometry>
      <material name="">
        <color rgba="0 0.055 0.525 1"/>
      </material>
    </visual>
    <collision>
      <origin rpy="0 0 0" xyz="0 0 0"/>
      <geometry>
        <mesh filename="file:///home/janchen/Documents/ros2/tidybot_ws/install/tidybot_description/share/tidybot_description/meshes/grippers/gen3_lite_2f/right_finger_dist_link.STL"/>
      </geometry>
    </collision>
  </link>
  <gazebo reference="right_finger_dist_link">
    <material>Gazebo/Blue</material>
  </gazebo>
  <joint name="right_finger_tip_joint" type="revolute">
    <origin rpy="0 0 0" xyz="-0.045636 0.020423 0"/>
    <parent link="right_finger_prox_link"/>
    <child link="right_finger_dist_link"/>
    <axis xyz="0 0 1"/>
    <limit effort="1000.0" lower="-0.50" upper="0.21" velocity="1000.0"/>
    <!--limit lower="-1.03" upper="0.21" effort="1000" velocity="1000" /-->
    <!-- <mimic joint="${prefix}right_finger_bottom_joint" multiplier="-0.676" offset="0.149" /> -->
    <dynamics damping="1.0" friction="1.0"/>
  </joint>
  <transmission name="right_finger_tip_joint_trans">
    <type>transmission_interface/SimpleTransmission</type>
    <joint name="right_finger_tip_joint"/>
    <actuator name="right_finger_tip_joint_motor">
      <mechanicalReduction>1</mechanicalReduction>
    </actuator>
  </transmission>
  <link name="left_finger_prox_link">
    <inertial>
      <origin rpy="0 0 0" xyz="0.020257 0.0063483 6.99E-05"/>
      <mass value="0.018385"/>
      <inertia ixx="2.29E-06" ixy="1.43E-06" ixz="0" iyy="4.56E-06" iyz="0" izz="4.77E-06"/>
    </inertial>
    <visual>
      <origin rpy="0 0 0" xyz="0 0 0"/>
      <geometry>
        <mesh filename="file:///home/janchen/Documents/ros2/tidybot_ws/install/tidybot_description/share/tidybot_description/meshes/grippers/gen3_lite_2f/left_finger_prox_link.STL"/>
      </geometry>
      <material name="">
        <color rgba="0.803 0.824 0.820 1"/>
      </material>
    </visual>
    <collision>
      <origin rpy="0 0 0" xyz="0 0 0"/>
      <geometry>
        <mesh filename="file:///home/janchen/Documents/ros2/tidybot_ws/install/tidybot_description/share/tidybot_description/meshes/grippers/gen3_lite_2f/left_finger_prox_link.STL"/>
      </geometry>
    </collision>
  </link>
  <gazebo reference="left_finger_prox_link">
    <material>Gazebo/Gray</material>
  </gazebo>
  <joint name="left_finger_bottom_joint" type="revolute">
    <origin rpy="0 1.5708 0" xyz="0 0.0305 0.070003"/>
    <parent link="gripper_base_link"/>
    <child link="left_finger_prox_link"/>
    <axis xyz="0 0 1"/>
    <limit effort="1000.0" lower="-0.96" upper="0.09" velocity="1000.0"/>
    <!-- <mimic joint="${prefix}right_finger_bottom_joint" multiplier="-1.0" offset="0.0" /> -->
    <dynamics damping="1.0" friction="1.0"/>
  </joint>
  <transmission name="left_finger_bottom_joint_trans">
    <type>transmission_interface/SimpleTransmission</type>
    <joint name="left_finger_bottom_joint"/>
    <actuator name="left_finger_bottom_joint_motor">
      <mechanicalReduction>1</mechanicalReduction>
    </actuator>
  </transmission>
  <link name="left_finger_dist_link">
    <inertial>
      <origin rpy="0 0 0" xyz="-0.018488 0.0011091 0"/>
      <mass value="0.010748"/>
      <inertia ixx="6.3E-07" ixy="3.2E-07" ixz="0" iyy="1.83E-06" iyz="0" izz="1.61E-06"/>
    </inertial>
    <visual>
      <origin rpy="0 0 0" xyz="0 0 0"/>
      <geometry>
        <mesh filename="file:///home/janchen/Documents/ros2/tidybot_ws/install/tidybot_description/share/tidybot_description/meshes/grippers/gen3_lite_2f/left_finger_dist_link.STL"/>
      </geometry>
      <material name="">
        <color rgba="0 0.055 0.525 1"/>
      </material>
    </visual>
    <collision>
      <origin rpy="0 0 0" xyz="0 0 0"/>
      <geometry>
        <mesh filename="file:///home/janchen/Documents/ros2/tidybot_ws/install/tidybot_description/share/tidybot_description/meshes/grippers/gen3_lite_2f/left_finger_dist_link.STL"/>
      </geometry>
    </collision>
  </link>
  <gazebo reference="left_finger_dist_link">
    <material>Gazebo/Blue</material>
  </gazebo>
  <joint name="left_finger_tip_joint" type="revolute">
    <origin rpy="0 0 0" xyz="-0.045636 -0.020423 6.9901E-05"/>
    <parent link="left_finger_prox_link"/>
    <child link="left_finger_dist_link"/>
    <axis xyz="0 0 -1"/>
    <limit effort="1000.0" lower="-0.50" upper="0.21" velocity="1000.0"/>
    <!--limit lower="-1.03" upper="0.21" effort="1000" velocity="1000" /-->
    <!-- <mimic joint="${prefix}right_finger_bottom_joint" multiplier="-0.676" offset="0.149" /> -->
    <dynamics damping="1.0" friction="1.0"/>
  </joint>
  <transmission name="left_finger_tip_joint_trans">
    <type>transmission_interface/SimpleTransmission</type>
    <joint name="left_finger_tip_joint"/>
    <actuator name="left_finger_tip_joint_motor">
      <mechanicalReduction>1</mechanicalReduction>
    </actuator>
  </transmission>
  <ros2_control name="GazeboSystem" type="system">
    <hardware>
      <plugin>gz_ros2_control/GazeboSimSystem</plugin>
    </hardware>
    <joint name="joint_x">
      <command_interface name="position"/>
      <state_interface name="position"/>
      <state_interface name="velocity"/>
      <param name="position_proportional_gain">0.1</param>
    </joint>
    <joint name="joint_y">
      <command_interface name="position"/>
      <state_interface name="position"/>
      <state_interface name="velocity"/>
      <param name="position_proportional_gain">0.1</param>
    </joint>
    <joint name="joint_th">
      <command_interface name="position"/>
      <state_interface name="position"/>
      <state_interface name="velocity"/>
      <param name="position_proportional_gain">0.1</param>
    </joint>
    <joint name="joint_1">
      <command_interface name="position"/>
      <state_interface name="position"/>
      <state_interface name="velocity"/>
      <param name="position_proportional_gain">0.1</param>
    </joint>
    <joint name="joint_2">
      <command_interface name="position"/>
      <state_interface name="position"/>
      <state_interface name="velocity"/>
      <param name="position_proportional_gain">0.1</param>
    </joint>
    <joint name="joint_3">
      <command_interface name="position"/>
      <state_interface name="position"/>
      <state_interface name="velocity"/>
      <param name="position_proportional_gain">0.1</param>
    </joint>
    <joint name="joint_4">
      <command_interface name="position"/>
      <state_interface name="position"/>
      <state_interface name="velocity"/>
      <param name="position_proportional_gain">0.1</param>
    </joint>
    <joint name="joint_5">
      <command_interface name="position"/>
      <state_interface name="position"/>
      <state_interface name="velocity"/>
      <param name="position_proportional_gain">0.1</param>
    </joint>
    <joint name="joint_6">
      <command_interface name="position"/>
      <state_interface name="position"/>
      <state_interface name="velocity"/>
      <param name="position_proportional_gain">0.1</param>
    </joint>
    <joint name="right_finger_bottom_joint">
      <command_interface name="position"/>
      <state_interface name="position"/>
      <state_interface name="velocity"/>
      <param name="position_proportional_gain">0.1</param>
    </joint>
    <joint name="right_finger_tip_joint">
      <command_interface name="position"/>
      <state_interface name="position"/>
      <state_interface name="velocity"/>
      <param name="position_proportional_gain">0.1</param>
    </joint>
    <joint name="left_finger_bottom_joint">
      <command_interface name="position"/>
      <state_interface name="position"/>
      <state_interface name="velocity"/>
      <param name="position_proportional_gain">0.1</param>
    </joint>
    <joint name="left_finger_tip_joint">
      <command_interface name="position"/>
      <state_interface name="position"/>
      <state_interface name="velocity"/>
      <param name="position_proportional_gain">0.1</param>
    </joint>
  </ros2_control>
  <gazebo>
    <plugin filename="gz_ros2_control-system" name="gz_ros2_control::GazeboSimROS2ControlPlugin">
      <parameters>/home/janchen/Documents/ros2/tidybot_ws/install/tidybot_description/share/tidybot_description/config/ros2_control.yaml</parameters>
      <robot_description_param>robot_description</robot_description_param>
    </plugin>
    <self_collide>true</self_collide>
  </gazebo>
</robot>
