<?xml version="1.0" ?>
<robot name="tidybot">
  <link name="world"/>
  <link name="base">
    <inertial>
      <origin rpy="0 0 0" xyz="0 0 0"/>
      <mass value="34"/>
      <inertia ixx="1e-09" ixy="0" ixz="0" iyy="1e-09" iyz="0" izz="1e-09"/>
    </inertial>
    <!-- Part kinova -->
    <visual>
      <origin rpy="0 -0 0" xyz="-0.3066 0.06523 0.085"/>
      <geometry>
        <mesh filename="file:///tidybot_description/meshes/base/tidybot++/Kinova.stl"/>
      </geometry>
      <material name="grey">
        <color rgba="0.5 0.5 0.5 1"/>
      </material>
    </visual>
    <collision>
      <origin rpy="0 -0 0" xyz="-0.3066 0.06523 0.085"/>
      <geometry>
        <mesh filename="file:///tidybot_description/meshes/base/tidybot++/Kinova.stl"/>
      </geometry>
    </collision>
  </link>
  <link name="base_camera_link"/>
  <joint name="base_camera_joint" type="fixed">
    <origin rpy="0 0.7853981634 0" xyz="0.2525 0.0 0.315"/>
    <parent link="base"/>
    <child link="base_camera_link"/>
    <visual>
      <origin rpy="0 0 0" xyz="0.2285 0.0 0.315"/>
      <geometry>
        <box size="0.1 0.1 0.1"/>
      </geometry>
      <material name="red">
        <color rgba="1 0 0 1"/>
      </material>
    </visual>
  </joint>
  <link name="joint_x_jointbody">
    <inertial>
      <origin rpy="0.0 0.0 0.0" xyz="0.0 0.0 0.0"/>
      <mass value="0.001"/>
      <inertia ixx="1e-09" ixy="0" ixz="0" iyy="1e-09" iyz="0" izz="1e-09"/>
    </inertial>
  </link>
  <joint name="joint_x" type="prismatic">
    <origin rpy="0.0 0.0 0.0" xyz="0.0 0.0 0.085"/>
    <parent link="world"/>
    <child link="joint_x_jointbody"/>
    <axis xyz="1 0 0"/>
    <limit effort="100" lower="-10.0" upper="10.0" velocity="1"/>
    <dynamics damping="1.0" friction="1.0"/>
  </joint>
  <link name="joint_y_jointbody">
    <inertial>
      <origin rpy="0.0 0.0 0.0" xyz="0.0 0.0 0.0"/>
      <mass value="0.001"/>
      <inertia ixx="1e-09" ixy="0" ixz="0" iyy="1e-09" iyz="0" izz="1e-09"/>
    </inertial>
  </link>
  <joint name="joint_y" type="prismatic">
    <origin rpy="0.0 0.0 0.0" xyz="0.0 0.0 0.0"/>
    <parent link="joint_x_jointbody"/>
    <child link="joint_y_jointbody"/>
    <axis xyz="0 1 0"/>
    <limit effort="100" lower="-10.0" upper="10.0" velocity="1"/>
    <dynamics damping="1.0" friction="1.0"/>
  </joint>
  <link name="joint_th_jointbody">
    <inertial>
      <origin rpy="0.0 0.0 0.0" xyz="0.0 0.0 0.0"/>
      <mass value="0.001"/>
      <inertia ixx="1e-09" ixy="0" ixz="0" iyy="1e-09" iyz="0" izz="1e-09"/>
    </inertial>
  </link>
  <joint name="joint_th" type="revolute">
    <origin rpy="0.0 0.0 0.0" xyz="0.0 0.0 0.0"/>
    <parent link="joint_y_jointbody"/>
    <child link="joint_th_jointbody"/>
    <axis xyz="0.0 0.0 1.0"/>
    <limit effort="100" lower="-10" upper="10" velocity="1"/>
    <dynamics damping="1.0" friction="1.0"/>
  </joint>
  <joint name="joint_th_offset" type="fixed">
    <origin rpy="0.0 0.0 0.0" xyz="-0.0 -0.0 -0.0"/>
    <parent link="joint_th_jointbody"/>
    <child link="base"/>
    <axis xyz="0.0 0.0 1.0"/>
    <limit effort="100" lower="0.0" upper="0.0" velocity="100"/>
  </joint>
  <material name="grey">
    <color rgba="0.5 0.5 0.5 1"/>
  </material>
  <joint name="arm_base_joint" type="fixed">
    <origin rpy="0 0 0" xyz="0.12 3.76986e-15 0.374775"/>
    <parent link="base"/>
    <child link="arm_base_link"/>
  </joint>
  <link name="arm_base_link">
    <inertial>
      <origin rpy="0 0 0" xyz="-0.000648 -0.000166 0.084487"/>
      <mass value="1.697"/>
      <inertia ixx="0.004622" ixy="9E-06" ixz="6E-05" iyy="0.004495" iyz="9E-06" izz="0.002079"/>
    </inertial>
    <visual>
      <origin rpy="0 0 0" xyz="0 0 0"/>
      <geometry>
        <mesh filename="file:///tidybot_description/meshes/arms/gen3_7dof/base_link.STL"/>
      </geometry>
      <material name="">
        <color rgba="0.75294 0.75294 0.75294 1"/>
      </material>
    </visual>
    <collision>
      <origin rpy="0 0 0" xyz="0 0 0"/>
      <geometry>
        <mesh filename="file:///tidybot_description/meshes/arms/gen3_7dof/base_link.STL"/>
      </geometry>
    </collision>
  </link>
  <link name="shoulder_link">
    <inertial>
      <origin rpy="0 0 0" xyz="-2.3E-05 -0.010364 -0.07336"/>
      <mass value="1.3773"/>
      <inertia ixx="0.00457" ixy="1E-06" ixz="2E-06" iyy="0.004831" iyz="0.000448" izz="0.001409"/>
    </inertial>
    <visual>
      <origin rpy="0 0 0" xyz="0 0 0"/>
      <geometry>
        <mesh filename="file:///tidybot_description/meshes/arms/gen3_7dof/shoulder_link.STL"/>
      </geometry>
      <material name="">
        <color rgba="0.75294 0.75294 0.75294 1"/>
      </material>
    </visual>
    <collision>
      <origin rpy="0 0 0" xyz="0 0 0"/>
      <geometry>
        <mesh filename="file:///tidybot_description/meshes/arms/gen3_7dof/shoulder_link.STL"/>
      </geometry>
    </collision>
  </link>
  <gazebo reference="shoulder_link">
    <material>Gazebo/Gray</material>
  </gazebo>
  <joint name="joint_1" type="continuous">
    <origin rpy="3.1416 2.7629E-18 -4.9305E-36" xyz="0 0 0.15643"/>
    <parent link="arm_base_link"/>
    <child link="shoulder_link"/>
    <axis xyz="0 0 1"/>
    <limit effort="39" velocity="1.3963"/>
  </joint>
  <link name="half_arm_1_link">
    <inertial>
      <origin rpy="0 0 0" xyz="-4.4E-05 -0.09958 -0.013278"/>
      <mass value="1.1636"/>
      <inertia ixx="0.011088" ixy="5E-06" ixz="0" iyy="0.001072" iyz="-0.000691" izz="0.011255"/>
    </inertial>
    <visual>
      <origin rpy="0 0 0" xyz="0 0 0"/>
      <geometry>
        <mesh filename="file:///tidybot_description/meshes/arms/gen3_7dof/half_arm_1_link.STL"/>
      </geometry>
      <material name="">
        <color rgba="0.75294 0.75294 0.75294 1"/>
      </material>
    </visual>
    <collision>
      <origin rpy="0 0 0" xyz="0 0 0"/>
      <geometry>
        <mesh filename="file:///tidybot_description/meshes/arms/gen3_7dof/half_arm_1_link.STL"/>
      </geometry>
    </collision>
  </link>
  <joint name="joint_2" type="revolute">
    <origin rpy="1.5708 2.1343E-17 -1.1102E-16" xyz="0 0.005375 -0.12838"/>
    <parent link="shoulder_link"/>
    <child link="half_arm_1_link"/>
    <axis xyz="0 0 1"/>
    <limit effort="39" lower="-2.24" upper="2.24" velocity="1.3963"/>
  </joint>
  <link name="half_arm_2_link">
    <inertial>
      <origin rpy="0 0 0" xyz="-4.4E-05 -0.006641 -0.117892"/>
      <mass value="1.1636"/>
      <inertia ixx="0.010932" ixy="0" ixz="-7E-06" iyy="0.011127" iyz="0.000606" izz="0.001043"/>
    </inertial>
    <visual>
      <origin rpy="0 0 0" xyz="0 0 0"/>
      <geometry>
        <mesh filename="file:///tidybot_description/meshes/arms/gen3_7dof/half_arm_2_link.STL"/>
      </geometry>
      <material name="">
        <color rgba="0.75294 0.75294 0.75294 1"/>
      </material>
    </visual>
    <collision>
      <origin rpy="0 0 0" xyz="0 0 0"/>
      <geometry>
        <mesh filename="file:///tidybot_description/meshes/arms/gen3_7dof/half_arm_2_link.STL"/>
      </geometry>
    </collision>
  </link>
  <joint name="joint_3" type="continuous">
    <origin rpy="-1.5708 1.2326E-32 -2.9122E-16" xyz="0 -0.21038 -0.006375"/>
    <parent link="half_arm_1_link"/>
    <child link="half_arm_2_link"/>
    <axis xyz="0 0 1"/>
    <limit effort="39" velocity="1.3963"/>
  </joint>
  <link name="forearm_link">
    <inertial>
      <origin rpy="0 0 0" xyz="-1.8E-05 -0.075478 -0.015006"/>
      <mass value="0.9302"/>
      <inertia ixx="0.008147" ixy="-1E-06" ixz="0" iyy="0.000631" iyz="-0.0005" izz="0.008316"/>
    </inertial>
    <visual>
      <origin rpy="0 0 0" xyz="0 0 0"/>
      <geometry>
        <mesh filename="file:///tidybot_description/meshes/arms/gen3_7dof/forearm_link.STL"/>
      </geometry>
      <material name="">
        <color rgba="0.75294 0.75294 0.75294 1"/>
      </material>
    </visual>
    <collision>
      <origin rpy="0 0 0" xyz="0 0 0"/>
      <geometry>
        <mesh filename="file:///tidybot_description/meshes/arms/gen3_7dof/forearm_link.STL"/>
      </geometry>
    </collision>
  </link>
  <joint name="joint_4" type="revolute">
    <origin rpy="1.5708 -6.6954E-17 -1.6653E-16" xyz="0 0.006375 -0.21038"/>
    <parent link="half_arm_2_link"/>
    <child link="forearm_link"/>
    <axis xyz="0 0 1"/>
    <limit effort="39" lower="-2.57" upper="2.57" velocity="1.3963"/>
  </joint>
  <link name="spherical_wrist_1_link">
    <inertial>
      <origin rpy="0 0 0" xyz="1E-06 -0.009432 -0.063883"/>
      <mass value="0.6781"/>
      <inertia ixx="0.001596" ixy="0" ixz="0" iyy="0.001607" iyz="0.000256" izz="0.000399"/>
    </inertial>
    <visual>
      <origin rpy="0 0 0" xyz="0 0 0"/>
      <geometry>
        <mesh filename="file:///tidybot_description/meshes/arms/gen3_7dof/spherical_wrist_1_link.STL"/>
      </geometry>
      <material name="">
        <color rgba="0.75294 0.75294 0.75294 1"/>
      </material>
    </visual>
    <collision>
      <origin rpy="0 0 0" xyz="0 0 0"/>
      <geometry>
        <mesh filename="file:///tidybot_description/meshes/arms/gen3_7dof/spherical_wrist_1_link.STL"/>
      </geometry>
    </collision>
  </link>
  <joint name="joint_5" type="continuous">
    <origin rpy="-1.5708 2.2204E-16 -6.373E-17" xyz="0 -0.20843 -0.006375"/>
    <parent link="forearm_link"/>
    <child link="spherical_wrist_1_link"/>
    <axis xyz="0 0 1"/>
    <limit effort="9" velocity="1.2218"/>
  </joint>
  <link name="spherical_wrist_2_link">
    <inertial>
      <origin rpy="0 0 0" xyz="1E-06 -0.045483 -0.00965"/>
      <mass value="0.6781"/>
      <inertia ixx="0.001641" ixy="0" ixz="0" iyy="0.00041" iyz="-0.000278" izz="0.001641"/>
    </inertial>
    <visual>
      <origin rpy="0 0 0" xyz="0 0 0"/>
      <geometry>
        <mesh filename="file:///tidybot_description/meshes/arms/gen3_7dof/spherical_wrist_2_link.STL"/>
      </geometry>
      <material name="">
        <color rgba="0.75294 0.75294 0.75294 1"/>
      </material>
    </visual>
    <collision>
      <origin rpy="0 0 0" xyz="0 0 0"/>
      <geometry>
        <mesh filename="file:///tidybot_description/meshes/arms/gen3_7dof/spherical_wrist_2_link.STL"/>
      </geometry>
    </collision>
  </link>
  <joint name="joint_6" type="revolute">
    <origin rpy="1.5708 9.2076E-28 -8.2157E-15" xyz="0 0.00017505 -0.10593"/>
    <parent link="spherical_wrist_1_link"/>
    <child link="spherical_wrist_2_link"/>
    <axis xyz="0 0 1"/>
    <limit effort="9" lower="-2.09" upper="2.09" velocity="1.2218"/>
  </joint>
  <link name="bracelet_link">
    <inertial>
      <origin rpy="0 0 0" xyz="0.000281 0.011402 -0.029798"/>
      <mass value="0.5"/>
      <inertia ixx="0.000587" ixy="3E-06" ixz="3E-06" iyy="0.000369" iyz="-0.000118" izz="0.000609"/>
    </inertial>
    <visual>
      <origin rpy="0 0 0" xyz="0 0 0"/>
      <geometry>
        <mesh filename="file:///tidybot_description/meshes/arms/gen3_7dof/bracelet_with_vision_link.STL"/>
      </geometry>
      <material name="">
        <color rgba="0.75294 0.75294 0.75294 1"/>
      </material>
    </visual>
    <collision>
      <origin rpy="0 0 0" xyz="0 0 0"/>
      <geometry>
        <mesh filename="file:///tidybot_description/meshes/arms/gen3_7dof/bracelet_with_vision_link.STL"/>
      </geometry>
    </collision>
  </link>
  <joint name="joint_7" type="continuous">
    <origin rpy="-1.5708 -5.5511E-17 9.6396E-17" xyz="0 -0.10593 -0.00017505"/>
    <parent link="spherical_wrist_2_link"/>
    <child link="bracelet_link"/>
    <axis xyz="0 0 1"/>
    <limit effort="9" velocity="1.2218"/>
  </joint>
  <link name="end_effector_link"/>
  <joint name="end_effector" type="fixed">
    <origin rpy="3.14159265358979 1.09937075168372E-32 0" xyz="0 0 -0.0615250000000001"/>
    <parent link="bracelet_link"/>
    <child link="end_effector_link"/>
    <axis xyz="0 0 0"/>
  </joint>
  <link name="arm_camera_link"/>
  <joint name="camera_module" type="fixed">
    <origin rpy="3.14159265358979 3.14159265358979 0" xyz="0 0.05639 -0.00405"/>
    <parent link="end_effector_link"/>
    <child link="arm_camera_link"/>
  </joint>
  <link name="camera_depth_frame"/>
  <joint name="depth_module" type="fixed">
    <origin rpy="3.14159265358979 3.14159265358979 0" xyz="0.0275 0.066 -0.00305"/>
    <parent link="end_effector_link"/>
    <child link="camera_depth_frame"/>
  </joint>
  <link name="camera_color_frame"/>
  <joint name="color_module" type="fixed">
    <origin rpy="3.14159265358979 3.14159265358979 0" xyz="0 0.05639 -0.00305"/>
    <parent link="end_effector_link"/>
    <child link="camera_color_frame"/>
  </joint>
  <!-- This line was removed by Kinova because we replaced the transmission file with our own 
    <xacro:include filename="$(find robotiq_2f_85_gripper_visualization)/urdf/robotiq_arg2f_transmission.xacro" /> -->
  <link name="tool_frame"/>
  <joint name="tool_frame_joint" type="fixed">
    <origin rpy="0 0 0" xyz="0 0 0.120"/>
    <parent link="end_effector_link"/>
    <child link="tool_frame"/>
    <axis xyz="0 0 0"/>
  </joint>
  <!-- This line was removed by Kinova because we replaced the transmission file with our own 
    <xacro:include filename="$(find robotiq_2f_85_gripper_visualization)/urdf/robotiq_arg2f_transmission.xacro" /> -->
  <!-- This joint was added by Kinova -->
  <joint name="gripper_base_joint" type="fixed">
    <parent link="end_effector_link"/>
    <child link="robotiq_arg2f_base_link"/>
    <origin xyz="0.0 0.0 0.0" rpy="3.1415927 -1.5707964 1.5707964"/>
  </joint>
  <!-- Robotiq 2F-85 Gripper - Simplified parallel-jaw gripper for Isaac Sim -->
  <!-- Base link (exported from Isaac Sim) -->
  <link name="robotiq_arg2f_base_link">
    <inertial>
      <origin xyz="0.0320809 0.0000006 0.0000228" rpy="0. 0. 0."/>
      <mass value="0.6098911"/>
      <inertia ixx="0.0004747" ixy="-0." ixz="0." iyy="0.0003629" iyz="0." izz="0.0005407"/>
    </inertial>
    <visual>
      <origin xyz="-0.000242 0. 0." rpy="0. 0. -1.5707964"/>
      <geometry>
        <mesh filename="file:///tidybot_description/meshes/grippers/robotiq_2f_85/robotiq_arg2f_85_base_link.stl"/>
      </geometry>
    </visual>
    <collision>
      <origin xyz="-0.000242 0. 0." rpy="0. 0. -1.5707964"/>
      <geometry>
        <mesh filename="file:///tidybot_description/meshes/grippers/robotiq_2f_85/robotiq_arg2f_85_base_link.stl"/>
      </geometry>
    </collision>
  </link>
  <!-- Left side links -->
  <link name="left_outer_knuckle">
    <inertial>
      <origin xyz="-0.012132 -0.000586 0." rpy="0. 0. 0."/>
      <mass value="0.0127346"/>
      <inertia ixx="0.0000003" ixy="0." ixz="0." iyy="0.0000021" iyz="0." izz="0.0000021"/>
    </inertial>
    <visual>
      <origin xyz="0.0292492 -0.0556365 0." rpy="0. 0. -0.0244589"/>
      <geometry>
        <mesh filename="file:///tidybot_description/meshes/grippers/robotiq_2f_85/robotiq_arg2f_85_outer_knuckle.stl"/>
      </geometry>
    </visual>
    <collision>
      <origin xyz="0.0292492 -0.0556365 0." rpy="0. 0. -0.0244589"/>
      <geometry>
        <mesh filename="file:///tidybot_description/meshes/grippers/robotiq_2f_85/robotiq_arg2f_85_outer_knuckle.stl"/>
      </geometry>
    </collision>
  </link>
  <link name="left_outer_finger">
    <inertial>
      <origin xyz="-0.0039245 -0.0185808 -0.0000055" rpy="0. 0. 0."/>
      <mass value="0.0391792"/>
      <inertia ixx="0.0000043" ixy="0." ixz="-0." iyy="0.0000109" iyz="-0." izz="0.0000132"/>
    </inertial>
    <visual>
      <origin xyz="0.062026 0.0503723 0." rpy="-3.1415927 0. 0."/>
      <geometry>
        <mesh filename="file:///tidybot_description/meshes/grippers/robotiq_2f_85/robotiq_arg2f_85_outer_finger.stl"/>
      </geometry>
    </visual>
    <collision>
      <origin xyz="0.062026 0.0503723 0." rpy="-3.1415927 0. 0."/>
      <geometry>
        <mesh filename="file:///tidybot_description/meshes/grippers/robotiq_2f_85/robotiq_arg2f_85_outer_finger.stl"/>
      </geometry>
    </collision>
  </link>
  <link name="left_inner_finger">
    <inertial>
      <origin xyz="0.0189383 -0.0286037 -0.0133" rpy="0. 0. 0."/>
      <mass value="0.0197616"/>
      <inertia ixx="0.000001" ixy="0." ixz="-0." iyy="0.0000028" iyz="-0." izz="0.0000032"/>
    </inertial>
    <visual>
      <origin xyz="0.071171 0.0956936 -0.0133" rpy="3.1415927 0. -0.0244594"/>
      <geometry>
        <mesh filename="file:///tidybot_description/meshes/grippers/robotiq_2f_85/robotiq_arg2f_85_inner_finger.stl"/>
      </geometry>
    </visual>
    <visual>
      <origin xyz="0.071171 0.0956936 -0.0133" rpy="3.1415927 0. -0.0244594"/>
      <geometry>
        <mesh filename="file:///tidybot_description/meshes/grippers/robotiq_2f_85/robotiq_arg2f_85_pad.stl"/>
      </geometry>
    </visual>
    <collision>
      <origin xyz="0.071171 0.0956936 -0.0133" rpy="3.1415927 0. -0.0244594"/>
      <geometry>
        <mesh filename="file:///tidybot_description/meshes/grippers/robotiq_2f_85/robotiq_arg2f_85_inner_finger.stl"/>
      </geometry>
    </collision>
    <collision>
      <origin xyz="0.071171 0.0956936 -0.0133" rpy="3.1415927 0. -0.0244594"/>
      <geometry>
        <mesh filename="file:///tidybot_description/meshes/grippers/robotiq_2f_85/robotiq_arg2f_85_pad.stl"/>
      </geometry>
    </collision>
  </link>
  <!-- Inner knuckles: collision removed to break closed-loop kinematics -->
  <link name="left_inner_knuckle">
    <inertial>
      <origin xyz="0.0181803 -0.0209509 0." rpy="0. 0. 0."/>
      <mass value="0.0273069"/>
      <inertia ixx="0.0000045" ixy="0.0000001" ixz="0." iyy="0.000008" iyz="0." izz="0.0000118"/>
    </inertial>
    <visual>
      <origin xyz="0.0483511 -0.1051343 0." rpy="0. 0. -0.0244597"/>
      <geometry>
        <mesh filename="file:///tidybot_description/meshes/grippers/robotiq_2f_85/robotiq_arg2f_85_inner_knuckle.stl"/>
      </geometry>
    </visual>
    <!-- Collision removed - allows direct joint control without kinematic loop -->
  </link>
  <!-- Right side links -->
  <link name="right_outer_knuckle">
    <inertial>
      <origin xyz="0.012132 0.000586 0." rpy="0. 0. 0."/>
      <mass value="0.0127346"/>
      <inertia ixx="0.0000003" ixy="0." ixz="-0." iyy="0.0000021" iyz="0." izz="0.0000021"/>
    </inertial>
    <visual>
      <origin xyz="-0.0292492 0.0556365 0." rpy="0. 0. 3.1171339"/>
      <geometry>
        <mesh filename="file:///tidybot_description/meshes/grippers/robotiq_2f_85/robotiq_arg2f_85_outer_knuckle.stl"/>
      </geometry>
    </visual>
    <collision>
      <origin xyz="-0.0292492 0.0556365 0." rpy="0. 0. 3.1171339"/>
      <geometry>
        <mesh filename="file:///tidybot_description/meshes/grippers/robotiq_2f_85/robotiq_arg2f_85_outer_knuckle.stl"/>
      </geometry>
    </collision>
  </link>
  <link name="right_outer_finger">
    <inertial>
      <origin xyz="-0.0039245 -0.0185808 -0.0000055" rpy="0. 0. 0."/>
      <mass value="0.0391792"/>
      <inertia ixx="0.0000043" ixy="0." ixz="-0." iyy="0.0000109" iyz="-0." izz="0.0000132"/>
    </inertial>
    <visual>
      <origin xyz="0.062026 0.0503723 0." rpy="3.1415927 0. 0."/>
      <geometry>
        <mesh filename="file:///tidybot_description/meshes/grippers/robotiq_2f_85/robotiq_arg2f_85_outer_finger.stl"/>
      </geometry>
    </visual>
    <collision>
      <origin xyz="0.062026 0.0503723 0." rpy="3.1415927 0. 0."/>
      <geometry>
        <mesh filename="file:///tidybot_description/meshes/grippers/robotiq_2f_85/robotiq_arg2f_85_outer_finger.stl"/>
      </geometry>
    </collision>
  </link>
  <link name="right_inner_finger">
    <inertial>
      <origin xyz="0.0189383 0.0286037 -0.0133" rpy="0. 0. 0."/>
      <mass value="0.0197616"/>
      <inertia ixx="0.000001" ixy="-0." ixz="0." iyy="0.0000028" iyz="0." izz="0.0000032"/>
    </inertial>
    <visual>
      <origin xyz="0.071171 -0.0956936 -0.0133" rpy="0. 0. 0.0244594"/>
      <geometry>
        <mesh filename="file:///tidybot_description/meshes/grippers/robotiq_2f_85/robotiq_arg2f_85_inner_finger.stl"/>
      </geometry>
    </visual>
    <visual>
      <origin xyz="0.071171 -0.0956936 -0.0133" rpy="0. 0. 0.0244594"/>
      <geometry>
        <mesh filename="file:///tidybot_description/meshes/grippers/robotiq_2f_85/robotiq_arg2f_85_pad.stl"/>
      </geometry>
    </visual>
    <collision>
      <origin xyz="0.071171 -0.0956936 -0.0133" rpy="0. 0. 0.0244594"/>
      <geometry>
        <mesh filename="file:///tidybot_description/meshes/grippers/robotiq_2f_85/robotiq_arg2f_85_inner_finger.stl"/>
      </geometry>
    </collision>
    <collision>
      <origin xyz="0.071171 -0.0956936 -0.0133" rpy="0. 0. 0.0244594"/>
      <geometry>
        <mesh filename="file:///tidybot_description/meshes/grippers/robotiq_2f_85/robotiq_arg2f_85_pad.stl"/>
      </geometry>
    </collision>
  </link>
  <link name="right_inner_knuckle">
    <inertial>
      <origin xyz="0.0181803 -0.0209509 0." rpy="0. 0. 0."/>
      <mass value="0.0273069"/>
      <inertia ixx="0.0000045" ixy="0.0000001" ixz="-0." iyy="0.000008" iyz="-0." izz="0.0000118"/>
    </inertial>
    <visual>
      <origin xyz="0.0483511 -0.1051343 0." rpy="0. 0. -0.0244597"/>
      <geometry>
        <mesh filename="file:///tidybot_description/meshes/grippers/robotiq_2f_85/robotiq_arg2f_85_inner_knuckle.stl"/>
      </geometry>
    </visual>
    <!-- Collision removed - allows direct joint control without kinematic loop -->
  </link>
  <!-- Left outer knuckle joint (leader) -->
  <joint name="finger_joint" type="revolute">
    <origin xyz="0.0546625 0.0306011 0." rpy="0. 0. -1.5707964"/>
    <parent link="robotiq_arg2f_base_link"/>
    <child link="left_outer_knuckle"/>
    <axis xyz="0. 0. -1."/>
    <limit lower="0." upper="0.8203047" effort="26." velocity="2.5562093"/>
  </joint>
  <!-- Left outer finger (revolute for Isaac Sim spring mechanism) -->
  <joint name="left_outer_finger_joint" type="revolute">
    <origin xyz="-0.0315263 -0.0037623 0." rpy="3.1415927 0. -0.0244589"/>
    <parent link="left_outer_knuckle"/>
    <child link="left_outer_finger"/>
    <axis xyz="0 0 1"/>
    <limit lower="0" upper="3.14" effort="100" velocity="100"/>
  </joint>
  <!-- Left inner finger joint -->
  <joint name="left_inner_finger_joint" type="revolute">
    <origin xyz="-0.0067834 -0.0470334 0.0133" rpy="0. 0. 0."/>
    <parent link="left_outer_finger"/>
    <child link="left_inner_finger"/>
    <axis xyz="0. 0. 1."/>
    <limit lower="-3.1415927" upper="3.1415927" effort="0." velocity="174.5329252"/>
  </joint>
  <!-- Left inner knuckle joint (connects inner finger to inner knuckle -->
  <joint name="left_inner_finger_knuckle_joint" type="revolute">
    <origin xyz="0.0177368 -0.0069505 -0.0133" rpy="3.1415927 0. -0.0244594"/>
    <parent link="left_inner_finger"/>
    <child link="left_inner_knuckle"/>
    <axis xyz="0. 0. 1."/>
    <limit lower="-3.1415927" upper="3.1415927" effort="0." velocity="174.5329252"/>
  </joint>
  <!-- Right outer knuckle joint -->
  <joint name="right_outer_knuckle_joint" type="revolute">
    <origin xyz="0.0546625 -0.0306011 0." rpy="3.1415927 0. -1.5707964"/>
    <parent link="robotiq_arg2f_base_link"/>
    <child link="right_outer_knuckle"/>
    <axis xyz="0. 0. -1."/>
    <limit lower="-3.14" upper="3.14" effort="0." velocity="174.5329252"/>
  </joint>
  <!-- Right outer finger (revolute for Isaac Sim spring mechanism) -->
  <joint name="right_outer_finger_joint" type="revolute">
    <origin xyz="0.0315263 0.0037623 0." rpy="3.1415927 0. 3.1171336"/>
    <parent link="right_outer_knuckle"/>
    <child link="right_outer_finger"/>
    <axis xyz="0 0 1"/>
    <limit lower="0.0" upper="3.14" effort="100" velocity="100"/>
  </joint>
  <!-- Right inner finger joint -->
  <joint name="right_inner_finger_joint" type="revolute">
    <origin xyz="-0.0067834 -0.0470334 -0.0133" rpy="3.1415927 0. 0."/>
    <parent link="right_outer_finger"/>
    <child link="right_inner_finger"/>
    <axis xyz="0. 0. 1."/>
    <limit lower="-3.1415927" upper="3.1415927" effort="0." velocity="174.5329252"/>
  </joint>
  <!-- Right inner knuckle joint -->
  <joint name="right_inner_finger_knuckle_joint" type="revolute">
    <origin xyz="0.0177368 0.0069505 -0.0133" rpy="0. 0. 0.0244594"/>
    <parent link="right_inner_finger"/>
    <child link="right_inner_knuckle"/>
    <axis xyz="0. 0. 1."/>
    <limit lower="-3.1415927" upper="3.1415927" effort="0." velocity="174.5329252"/>
  </joint>
</robot>
